Workbook

Sheet Hướng dẫn
A1: Bảng báo giá chi tiết: từ ý tưởng đến vận hành
A2: Landing page, website, CMS, CRM, hệ thống quản lý và Zalo Mini App.
A4: Cách dùng
A5: 1 | B5: Mở sheet Thông số, nhập đơn giá ngày công theo vai trò và các hệ số (quản lý dự án, dự phòng, VAT, tỷ lệ thanh toán).
A6: 2 | B6: Sheet Hạng mục liệt kê mọi công việc. Sửa ngày công (chữ xanh) nếu ước tính của bạn khác. Cột gói cho biết hạng mục nào nằm trong gói nào.
A7: 3 | B7: Sheet Gói cấp độ là bảng 4 cấp Rẻ, Cơ bản, Nâng cao, Cao cấp theo kiểu bảng chức năng website (Có/Không, giá ở đầu cột). Sheet So sánh gói và Tổng hợp gói là 6 gói theo loại sản phẩm. Sheet So sánh gói là bảng Có/Không cho khách xem nhanh từng gói gồm gì. Sheet Tổng hợp gói cho giá chi tiết theo giai đoạn của 6 gói. Cả hai tính tự động.
A8: 4 | B8: Muốn báo giá riêng: ở sheet Hạng mục đặt 1 vào cột Chọn cho khách (nền vàng) cho các hạng mục khách cần, 0 cho phần còn lại.
A9: 5 | B9: Sheet Báo giá khách tự tổng hợp theo giai đoạn, thêm quản lý dự án, dự phòng, chiết khấu, VAT và lịch thanh toán. Nhập tên khách, dự án, ngày ở các ô vàng rồi gửi cho khách.
A10: 6 | B10: Sheet Vận hành tách riêng từng khoản phí hằng tháng: VPS, hosting, tên miền, SSL, monitoring, alert, sao lưu, bảo trì. Có 3 gói Cơ bản, Tiêu chuẩn, Nâng cao. Chọn gói ở ô Gói vận hành hàng tháng trong Báo giá khách.
A11: Giá thị trường
A12: B | B12: Sheet Bảng giá đề xuất là giá chào đã đối chiếu thị trường Việt Nam: 4 cấp độ website, giải pháp Mini App, CRM, hệ thống quản lý, module lẻ và phí hạ tầng, kèm nguồn tham khảo. Giá đề xuất ở các sheet So sánh gói, Gói cấp độ, Tổng hợp gói đều lấy từ sheet này.
A13: Báo giá riêng cho khách
A14: A | B14: Mỗi khách có 2 sheet: Báo giá (bản gửi khách) và Chi tiết (chọn hạng mục, chỉnh ngày công riêng). Sheet mẫu là TT Anh ngữ ABC. Để làm khách mới: bấm chuột phải vào tên sheet, chọn Move or Copy, tick Create a copy. Chọn cả hai sheet cùng lúc (giữ Ctrl) để bản sao vẫn nối đúng với nhau, rồi đổi tên.
A15: Quy ước màu
A16: Chữ xanh | B16: Dữ liệu nhập vào, có thể sửa.
A17: Nền vàng | B17: Ô cần điền hoặc giả định quan trọng.
A18: Chữ đen | B18: Công thức, không sửa.
A19: Lưu ý
A20: ! | B20: Toàn bộ đơn giá, ngày công và hệ số trong file là giả định mẫu do Claude đề xuất để bạn chỉnh. Chưa phải bảng giá chính thức của bạn.
A21: ! | B21: Dòng dữ liệu mẫu: Báo giá khách đang điền sẵn ví dụ Công ty ABC với lựa chọn Website + CMS. Thay bằng thông tin khách thật.

Sheet Bảng giá đề xuất
A1: Bảng giá đề xuất, đối chiếu thị trường Việt Nam
A2: Giá chào (cột chữ xanh nền vàng) đặt theo mặt bằng giá thị trường đã khảo sát, chưa gồm VAT. Chi phí nội bộ tính từ ước tính công x đơn giá Senior Dev trong Thông số.
A4: A. Website theo cấp độ (rẻ, cơ bản, nâng cao, cao cấp)
A5: Gói / Module | B5: Hình thức thực hiện | C5: Nội dung chính | D5: Thị trường thấp (VND) | E5: Thị trường cao (VND) | F5: Giá đề xuất (VND, chưa VAT) | G5: So với thị trường | H5: Ước tính công (ngày) | I5: Chi phí nội bộ (VND) | J5: Biên lợi nhuận | K5: Nguồn tham khảo
A6: Gói Rẻ | B6: Giao diện mẫu tùy chỉnh theo thương hiệu | C6: Landing page 1 trang, responsive, form liên hệ gửi email, SEO cơ bản, tên miền + SSL | D6: 3000000 | E6: 10000000 | F6: 5000000 | G6: =IF(F6="","",IF(D6="","Theo thỏa thuận",IF(F6<D6,"Thấp hơn khoảng thị trường",IF(AND(E6<>"",F6>E6),"Cao hơn khoảng thị trường","Trong khoảng thị trường")))) -> Trong khoảng thị trường | H6: 2.5 | I6: =H6*INDEX('Thông số'!$B$6:$B$10,MATCH("Senior Dev",'Thông số'!$A$6:$A$10,0))*'Thông số'!$B$26 -> 3500000 | J6: =IF(OR(F6="",F6=0),"",1-I6/F6) -> 0.3 | K6: Bizfly: landing 3 đến 10 triệu. Giao diện mẫu 2 đến 3 triệu.
A7: Gói Cơ bản | B7: Giao diện mẫu nâng cấp | C7: Website giới thiệu 5 trang, responsive, form email, tối ưu tốc độ, Google Analytics | D7: 7000000 | E7: 25000000 | F7: 12000000 | G7: =IF(F7="","",IF(D7="","Theo thỏa thuận",IF(F7<D7,"Thấp hơn khoảng thị trường",IF(AND(E7<>"",F7>E7),"Cao hơn khoảng thị trường","Trong khoảng thị trường")))) -> Trong khoảng thị trường | H7: 6 | I7: =H7*INDEX('Thông số'!$B$6:$B$10,MATCH("Senior Dev",'Thông số'!$A$6:$A$10,0))*'Thông số'!$B$26 -> 8400000 | J7: =IF(OR(F7="",F7=0),"",1-I7/F7) -> 0.3 | K7: Bizfly: website giới thiệu 7 đến 25 triệu. Expro 7,9 triệu, Tomaz 8,5 triệu.
A8: Gói Nâng cao | B8: Thiết kế riêng + CMS | C8: Website thiết kế riêng, tự cập nhật bài viết và trang (CMS), SEO, đa ngôn ngữ nhẹ, thư viện ảnh | D8: 15000000 | E8: 40000000 | F8: 28000000 | G8: =IF(F8="","",IF(D8="","Theo thỏa thuận",IF(F8<D8,"Thấp hơn khoảng thị trường",IF(AND(E8<>"",F8>E8),"Cao hơn khoảng thị trường","Trong khoảng thị trường")))) -> Trong khoảng thị trường | H8: 14 | I8: =H8*INDEX('Thông số'!$B$6:$B$10,MATCH("Senior Dev",'Thông số'!$A$6:$A$10,0))*'Thông số'!$B$26 -> 19600000 | J8: =IF(OR(F8="",F8=0),"",1-I8/F8) -> 0.3 | K8: Bizfly: website doanh nghiệp 15 đến 40 triệu. MONA: lập trình riêng 12 đến 35 triệu.
A9: Gói Cao cấp | B9: Lập trình riêng (custom) | C9: UI/UX riêng, tốc độ cao, tích hợp thanh toán, CRM, Zalo OA, chức năng theo yêu cầu | D9: 39000000 | E9: 60000000 | F9: 45000000 | G9: =IF(F9="","",IF(D9="","Theo thỏa thuận",IF(F9<D9,"Thấp hơn khoảng thị trường",IF(AND(E9<>"",F9>E9),"Cao hơn khoảng thị trường","Trong khoảng thị trường")))) -> Trong khoảng thị trường | H9: 26 | I9: =H9*INDEX('Thông số'!$B$6:$B$10,MATCH("Senior Dev",'Thông số'!$A$6:$A$10,0))*'Thông số'!$B$26 -> 36400000 | J9: =IF(OR(F9="",F9=0),"",1-I9/F9) -> 0.19111111 | K9: Bizfly: lập trình riêng từ 40 triệu. Bảng tham khảo bạn cung cấp: 39 đến 60 triệu trở lên.
A11: B. Giải pháp tùy chỉnh theo loại sản phẩm
A12: Gói / Module | B12: Hình thức thực hiện | C12: Nội dung chính | D12: Thị trường thấp (VND) | E12: Thị trường cao (VND) | F12: Giá đề xuất (VND, chưa VAT) | G12: So với thị trường | H12: Ước tính công (ngày) | I12: Chi phí nội bộ (VND) | J12: Biên lợi nhuận | K12: Nguồn tham khảo
A13: Zalo Mini App cơ bản | B13: Lập trình riêng (React + ZaUI) | C13: Giới thiệu, đặt lịch hoặc điểm danh, lưu dữ liệu, đồng bộ Excel/OneDrive, gửi duyệt Zalo | D13: 25000000 | E13: 45000000 | F13: 30000000 | G13: =IF(F13="","",IF(D13="","Theo thỏa thuận",IF(F13<D13,"Thấp hơn khoảng thị trường",IF(AND(E13<>"",F13>E13),"Cao hơn khoảng thị trường","Trong khoảng thị trường")))) -> Trong khoảng thị trường | H13: 16 | I13: =H13*INDEX('Thông số'!$B$6:$B$10,MATCH("Senior Dev",'Thông số'!$A$6:$A$10,0))*'Thông số'!$B$26 -> 22400000 | J13: =IF(OR(F13="",F13=0),"",1-I13/F13) -> 0.25333333 | K13: Thiết kế riêng Mini App giới thiệu + đặt lịch: 25 đến 45 triệu (tổng hợp từ bảng giá các đơn vị). Thuê nền tảng SaaS 10,8 triệu/năm.
A14: Zalo Mini App nâng cao | B14: Lập trình riêng + backend | C14: Bán hàng, giỏ hàng, tích điểm, thẻ thành viên, thanh toán, ZNS, quản trị web | D14: 45000000 | E14: 110000000 | F14: 70000000 | G14: =IF(F14="","",IF(D14="","Theo thỏa thuận",IF(F14<D14,"Thấp hơn khoảng thị trường",IF(AND(E14<>"",F14>E14),"Cao hơn khoảng thị trường","Trong khoảng thị trường")))) -> Trong khoảng thị trường | H14: 38 | I14: =H14*INDEX('Thông số'!$B$6:$B$10,MATCH("Senior Dev",'Thông số'!$A$6:$A$10,0))*'Thông số'!$B$26 -> 53200000 | J14: =IF(OR(F14="",F14=0),"",1-I14/F14) -> 0.24 | K14: Mini App bán hàng 45 đến 90 triệu, tích điểm 60 đến 110 triệu.
A15: CRM tùy chỉnh gọn | B15: Lập trình riêng | C15: Khách hàng, pipeline kanban, nhắc việc, báo giá PDF, báo cáo doanh số, phân quyền | D15: 60000000 | E15: 400000000 | F15: 85000000 | G15: =IF(F15="","",IF(D15="","Theo thỏa thuận",IF(F15<D15,"Thấp hơn khoảng thị trường",IF(AND(E15<>"",F15>E15),"Cao hơn khoảng thị trường","Trong khoảng thị trường")))) -> Trong khoảng thị trường | H15: 45 | I15: =H15*INDEX('Thông số'!$B$6:$B$10,MATCH("Senior Dev",'Thông số'!$A$6:$A$10,0))*'Thông số'!$B$26 -> 63000000 | J15: =IF(OR(F15="",F15=0),"",1-I15/F15) -> 0.25882353 | K15: Phần mềm theo yêu cầu 60 đến 400 triệu (CIT). CRM sẵn có MISA AMIS từ 55.000/người/tháng.
A16: Hệ thống quản lý vận hành | B16: Lập trình riêng | C16: Ví dụ trung tâm giáo dục: học viên, nhân sự, lịch, điểm danh, học phí, lương, báo cáo, dashboard | D16: 60000000 | E16: 400000000 | F16: 160000000 | G16: =IF(F16="","",IF(D16="","Theo thỏa thuận",IF(F16<D16,"Thấp hơn khoảng thị trường",IF(AND(E16<>"",F16>E16),"Cao hơn khoảng thị trường","Trong khoảng thị trường")))) -> Trong khoảng thị trường | H16: 85 | I16: =H16*INDEX('Thông số'!$B$6:$B$10,MATCH("Senior Dev",'Thông số'!$A$6:$A$10,0))*'Thông số'!$B$26 -> 1.19e+08 | J16: =IF(OR(F16="",F16=0),"",1-I16/F16) -> 0.25625 | K16: Phần mềm theo yêu cầu 60 đến 400 triệu, bảo trì khoảng 10 đến 20%/năm (CIT).
A18: C. Module và chức năng lẻ (cộng thêm vào gói)
A19: Chức năng | B19: Hình thức | C19: Mô tả | D19: Thị trường thấp (VND) | E19: Thị trường cao (VND) | F19: Giá đề xuất (VND, chưa VAT) | G19: So với thị trường | H19: Ước tính công (ngày) | I19: Chi phí nội bộ (VND) | J19: Biên lợi nhuận | K19: Nguồn tham khảo
A20: Popup thông báo | B20: Chức năng thêm | C20: Hiển thị ảnh hoặc thông báo khi khách vào web | D20: 500000 | E20: 500000 | F20: 500000 | G20: =IF(F20="","",IF(D20="","Theo thỏa thuận",IF(F20<D20,"Thấp hơn khoảng thị trường",IF(AND(E20<>"",F20>E20),"Cao hơn khoảng thị trường","Trong khoảng thị trường")))) -> Trong khoảng thị trường | H20: 0.25 | I20: =H20*INDEX('Thông số'!$B$6:$B$10,MATCH("Senior Dev",'Thông số'!$A$6:$A$10,0))*'Thông số'!$B$26 -> 350000 | J20: =IF(OR(F20="",F20=0),"",1-I20/F20) -> 0.3 | K20: Bảng tham khảo bạn cung cấp: 500.000.
A21: Google Dịch (đa ngôn ngữ nhanh) | B21: Chức năng thêm | C21: Tích hợp công cụ dịch trực tiếp trên trang | D21: 500000 | E21: 500000 | F21: 500000 | G21: =IF(F21="","",IF(D21="","Theo thỏa thuận",IF(F21<D21,"Thấp hơn khoảng thị trường",IF(AND(E21<>"",F21>E21),"Cao hơn khoảng thị trường","Trong khoảng thị trường")))) -> Trong khoảng thị trường | H21: 0.25 | I21: =H21*INDEX('Thông số'!$B$6:$B$10,MATCH("Senior Dev",'Thông số'!$A$6:$A$10,0))*'Thông số'!$B$26 -> 350000 | J21: =IF(OR(F21="",F21=0),"",1-I21/F21) -> 0.3 | K21: Bảng tham khảo bạn cung cấp: 500.000.
A22: Đa ngôn ngữ Việt/Anh đầy đủ | B22: Chức năng thêm | C22: Nội dung hai ngôn ngữ, chuyển đổi, SEO từng ngôn ngữ | F22: 4000000 | G22: =IF(F22="","",IF(D22="","Theo thỏa thuận",IF(F22<D22,"Thấp hơn khoảng thị trường",IF(AND(E22<>"",F22>E22),"Cao hơn khoảng thị trường","Trong khoảng thị trường")))) -> Theo thỏa thuận | H22: 2 | I22: =H22*INDEX('Thông số'!$B$6:$B$10,MATCH("Senior Dev",'Thông số'!$A$6:$A$10,0))*'Thông số'!$B$26 -> 2800000 | J22: =IF(OR(F22="",F22=0),"",1-I22/F22) -> 0.3 | K22: Giá đề xuất của Claude, chưa có số thị trường.
A23: Đẩy tin tức mới | B23: Chức năng thêm | C23: Hiển thị tin tức, thông báo động cho khách truy cập | D23: 1500000 | E23: 1500000 | F23: 1500000 | G23: =IF(F23="","",IF(D23="","Theo thỏa thuận",IF(F23<D23,"Thấp hơn khoảng thị trường",IF(AND(E23<>"",F23>E23),"Cao hơn khoảng thị trường","Trong khoảng thị trường")))) -> Trong khoảng thị trường | H23: 1 | I23: =H23*INDEX('Thông số'!$B$6:$B$10,MATCH("Senior Dev",'Thông số'!$A$6:$A$10,0))*'Thông số'!$B$26 -> 1400000 | J23: =IF(OR(F23="",F23=0),"",1-I23/F23) -> 0.066666667 | K23: Bảng tham khảo bạn cung cấp: 1.500.000.
A24: Popup form thu thông tin (lead form) | B24: Chức năng thêm | C24: Thu thập thông tin khách hàng, gửi về email hoặc Google Sheet | F24: 1500000 | G24: =IF(F24="","",IF(D24="","Theo thỏa thuận",IF(F24<D24,"Thấp hơn khoảng thị trường",IF(AND(E24<>"",F24>E24),"Cao hơn khoảng thị trường","Trong khoảng thị trường")))) -> Theo thỏa thuận | H24: 1 | I24: =H24*INDEX('Thông số'!$B$6:$B$10,MATCH("Senior Dev",'Thông số'!$A$6:$A$10,0))*'Thông số'!$B$26 -> 1400000 | J24: =IF(OR(F24="",F24=0),"",1-I24/F24) -> 0.066666667 | K24: Thị trường: theo yêu cầu. Giá đề xuất của Claude.
A25: Chat Zalo OA / Live chat | B25: Tích hợp | C25: Kết nối Zalo OA hoặc live chat vào website | F25: 3000000 | G25: =IF(F25="","",IF(D25="","Theo thỏa thuận",IF(F25<D25,"Thấp hơn khoảng thị trường",IF(AND(E25<>"",F25>E25),"Cao hơn khoảng thị trường","Trong khoảng thị trường")))) -> Theo thỏa thuận | H25: 2 | I25: =H25*INDEX('Thông số'!$B$6:$B$10,MATCH("Senior Dev",'Thông số'!$A$6:$A$10,0))*'Thông số'!$B$26 -> 2800000 | J25: =IF(OR(F25="",F25=0),"",1-I25/F25) -> 0.066666667 | K25: Thị trường: theo thỏa thuận. Giá đề xuất của Claude.
A26: Tích hợp CRM | B26: Tích hợp | C26: Đẩy lead từ website vào phần mềm CRM | F26: 6000000 | G26: =IF(F26="","",IF(D26="","Theo thỏa thuận",IF(F26<D26,"Thấp hơn khoảng thị trường",IF(AND(E26<>"",F26>E26),"Cao hơn khoảng thị trường","Trong khoảng thị trường")))) -> Theo thỏa thuận | H26: 3 | I26: =H26*INDEX('Thông số'!$B$6:$B$10,MATCH("Senior Dev",'Thông số'!$A$6:$A$10,0))*'Thông số'!$B$26 -> 4200000 | J26: =IF(OR(F26="",F26=0),"",1-I26/F26) -> 0.3 | K26: Thị trường: theo thỏa thuận. Giá đề xuất của Claude.
A27: Cổng thanh toán (VNPay, MoMo, QR) | B27: Tích hợp | C27: Thanh toán trực tuyến, đối soát đơn | F27: 8000000 | G27: =IF(F27="","",IF(D27="","Theo thỏa thuận",IF(F27<D27,"Thấp hơn khoảng thị trường",IF(AND(E27<>"",F27>E27),"Cao hơn khoảng thị trường","Trong khoảng thị trường")))) -> Theo thỏa thuận | H27: 4 | I27: =H27*INDEX('Thông số'!$B$6:$B$10,MATCH("Senior Dev",'Thông số'!$A$6:$A$10,0))*'Thông số'!$B$26 -> 5600000 | J27: =IF(OR(F27="",F27=0),"",1-I27/F27) -> 0.3 | K27: Thị trường: theo thỏa thuận. Giá đề xuất của Claude.
A28: Giỏ hàng và bán hàng cơ bản | B28: Module | C28: Quản lý sản phẩm, giỏ hàng, đặt hàng trực tuyến, email đơn hàng | D28: 6000000 | E28: 20000000 | F28: 15000000 | G28: =IF(F28="","",IF(D28="","Theo thỏa thuận",IF(F28<D28,"Thấp hơn khoảng thị trường",IF(AND(E28<>"",F28>E28),"Cao hơn khoảng thị trường","Trong khoảng thị trường")))) -> Trong khoảng thị trường | H28: 8 | I28: =H28*INDEX('Thông số'!$B$6:$B$10,MATCH("Senior Dev",'Thông số'!$A$6:$A$10,0))*'Thông số'!$B$26 -> 11200000 | J28: =IF(OR(F28="",F28=0),"",1-I28/F28) -> 0.25333333 | K28: Bảng tham khảo bạn cung cấp: website bán hàng 6 đến 20 triệu.
A29: Nhập, xuất Excel | B29: Chức năng thêm | C29: Nhập danh sách từ Excel, xuất báo cáo | F29: 3000000 | G29: =IF(F29="","",IF(D29="","Theo thỏa thuận",IF(F29<D29,"Thấp hơn khoảng thị trường",IF(AND(E29<>"",F29>E29),"Cao hơn khoảng thị trường","Trong khoảng thị trường")))) -> Theo thỏa thuận | H29: 1.5 | I29: =H29*INDEX('Thông số'!$B$6:$B$10,MATCH("Senior Dev",'Thông số'!$A$6:$A$10,0))*'Thông số'!$B$26 -> 2100000 | J29: =IF(OR(F29="",F29=0),"",1-I29/F29) -> 0.3 | K29: Giá đề xuất của Claude.
A31: D. Phí hạ tầng và duy trì (nhà cung cấp tính, chuyển tiếp theo hóa đơn)
A32: Khoản phí | B32: Chu kỳ | C32: Ghi chú | D32: Thị trường thấp (VND) | E32: Thị trường cao (VND) | F32: Dùng trong báo giá (VND) | G32: So với thị trường | K32: Nguồn tham khảo
A33: Tên miền quốc tế (.com, .net) | B33: năm | C33: Gia hạn hằng năm | D33: 200000 | E33: 500000 | F33: 400000 | G33: =IF(F33<D33,"Thấp hơn khoảng thị trường",IF(F33>E33,"Cao hơn khoảng thị trường","Trong khoảng thị trường")) -> Trong khoảng thị trường | K33: MONA: 200.000 đến 500.000/năm.
A34: Tên miền Việt Nam (.vn, .com.vn) | B34: năm | C34: Gia hạn hằng năm | D34: 600000 | E34: 1200000 | F34: 800000 | G34: =IF(F34<D34,"Thấp hơn khoảng thị trường",IF(F34>E34,"Cao hơn khoảng thị trường","Trong khoảng thị trường")) -> Trong khoảng thị trường | K34: MONA: 600.000 đến 1.200.000/năm.
A35: Hosting website tĩnh / CDN | B35: năm | C35: Cho landing page và website giới thiệu | D35: 500000 | E35: 2000000 | F35: 1200000 | G35: =IF(F35<D35,"Thấp hơn khoảng thị trường",IF(F35>E35,"Cao hơn khoảng thị trường","Trong khoảng thị trường")) -> Trong khoảng thị trường | K35: MONA: 500.000 đến 2.000.000/năm. Bảng của bạn: 1 đến 5 triệu.
A36: VPS cho ứng dụng, CMS, CRM | B36: năm | C36: 2 vCPU / 4 GB RAM | D36: 1000000 | E36: 5000000 | F36: 4200000 | G36: =IF(F36<D36,"Thấp hơn khoảng thị trường",IF(F36>E36,"Cao hơn khoảng thị trường","Trong khoảng thị trường")) -> Trong khoảng thị trường | K36: Bảng tham khảo bạn cung cấp: 1 đến 5 triệu/năm.
A37: Chứng chỉ SSL | B37: năm | C37: Let's Encrypt miễn phí, trả phí nếu khách yêu cầu | D37: 0 | E37: 2000000 | F37: 0 | G37: =IF(F37<D37,"Thấp hơn khoảng thị trường",IF(F37>E37,"Cao hơn khoảng thị trường","Trong khoảng thị trường")) -> Trong khoảng thị trường | K37: Bảng bạn cung cấp: miễn phí hoặc 500.000 đến 2.000.000/năm.
A38: Bảo trì website cơ bản: giám sát, cảnh báo, sao lưu, 1 giờ hỗ trợ/tháng | B38: năm | C38: Giám sát, cảnh báo, sao lưu, hỗ trợ | D38: 2000000 | E38: 5000000 | F38: ='Vận hành'!I23*12 -> 4860000 | G38: =IF(F38<D38,"Thấp hơn khoảng thị trường",IF(F38>E38,"Cao hơn khoảng thị trường","Trong khoảng thị trường")) -> Trong khoảng thị trường | K38: MONA: bảo trì 2 đến 5 triệu/năm. Bizfly: 1 đến 5 triệu/tháng cho gói đầy đủ.
A40: Nguồn khảo sát (truy cập 05/10/2026, mang tính tham khảo, không phải cam kết giá)
A41: Bizfly, chi phí thiết kế website: https://bizfly.vn/techblog/chi-phi-thiet-ke-website.html
A42: MONA Media, bảng giá thiết kế website: https://mona.media/bang-gia-thiet-ke-website/
A43: MONA Media, chi phí duy trì website: https://mona.media/chi-phi-duy-tri-website/
A44: MONA Media, web theo yêu cầu (12 đến 35 triệu): https://mona.media/thiet-ke-va-lap-trinh-web-theo-yeu-cau/
A45: Gói theo cấp độ: Expro (4,7 / 7,9 / 11,9 / 15,9 triệu), Tomaz (6,9 / 8,5 / 15,9 triệu), Bictweb (1,5 đến 15 triệu): expro.vn, tomaz.vn, bictweb.vn
...

Sheet Thông số
A1: Thông số báo giá
A2: Chỉ sửa các ô chữ xanh nền vàng. Mọi sheet khác tự tính lại theo các thông số này.
A4: Đơn giá ngày công theo vai trò
A5: Vai trò | B5: Đơn giá (VND/ngày) | C5: Ghi chú
A6: PM/BA | B6: 1500000 | C6: Quản lý dự án, phân tích nghiệp vụ, tài liệu, đào tạo.
A7: UI/UX | B7: 1500000 | C7: Thiết kế giao diện, prototype.
A8: Senior Dev | B8: 2000000 | C8: Lập trình frontend/backend, kiến trúc, tích hợp.
A9: DevOps | B9: 2000000 | C9: Hạ tầng, triển khai, CI/CD, giám sát.
A10: QA | B10: 1000000 | C10: Kiểm thử chức năng, hồi quy, hiệu năng.
A12: Hệ số và điều kiện thương mại
A13: Thông số | B13: Giá trị | C13: Ghi chú
A14: Quản lý dự án (% trên tạm tính) | B14: 0.08 | C14: Họp tiến độ hàng tuần, báo cáo, điều phối. Giả định mẫu.
A15: Dự phòng rủi ro (% trên phần đã gồm quản lý) | B15: 0.1 | C15: Dành cho thay đổi nhỏ trong phạm vi. Giả định mẫu.
A16: Thuế VAT | B16: 0.1 | C16: Xác nhận mức VAT đang áp dụng với kế toán trước khi gửi khách.
A17: Số ngày công thực tế/tuần/người | B17: 5 | C17: Dùng để ước tính thời gian triển khai.
A18: Hiệu suất làm việc | B18: 0.8 | C18: Trừ họp, chờ phản hồi của khách. Giả định mẫu.
A19: Thanh toán đợt 1: ký hợp đồng | B19: 0.3 | C19: Tổng 3 đợt phải bằng 100%.
A20: Thanh toán đợt 2: nghiệm thu thiết kế / bản demo | B20: 0.4
A21: Thanh toán đợt 3: nghiệm thu và bàn giao | B21: 0.3
A22: Hiệu lực báo giá (ngày) | B22: 30
A23: Số vòng chỉnh sửa mỗi giai đoạn thiết kế | B23: 2 | C23: Vòng thêm tính theo đơn giá ngày công.
A24: Thời gian bảo hành lỗi (ngày) | B24: 30 | C24: Tính từ ngày nghiệm thu.
A25: Kiểm tra tổng 3 đợt thanh toán | B25: =IF(ROUND(SUM(B19:B21),4)=1,"Đúng 100%","Sai: tổng khác 100%") -> Đúng 100%
A26: Hệ số điều chỉnh đơn giá (tái sử dụng thành phần có sẵn, mặt bằng giá thị trường) | B26: 0.7 | C26: Nhân với mọi đơn giá ngày công. 70% nghĩa là mức thực tế bằng 70% đơn giá nhập ở trên, do tái sử dụng thành phần đã làm sẵn (đăng nhập, bảng dữ liệu, điểm danh, đồng bộ Excel) và để sát giá thị trường Việt Nam. Nhập 100% để tính đủ.

Sheet Hạng mục
A1: Bảng hạng mục chi tiết
A2: Số 1 trong cột gói nghĩa là hạng mục đã gồm trong gói. Cột Chọn cho khách dùng để lập báo giá riêng ở sheet Báo giá khách.
A5: Mã | B5: Giai đoạn | C5: Hạng mục | D5: Đầu ra bàn giao | E5: Vai trò | F5: Ngày công | G5: Đơn giá/ngày (VND) | H5: Thành tiền (VND) | I5: Landing page | J5: Website giới thiệu | K5: Website + CMS | L5: CRM | M5: Hệ thống quản lý | N5: Zalo Mini App | O5: Chọn cho khách (1/0) | P5: Ngày công đã chọn | Q5: Thành tiền đã chọn (VND) | R5: Loại | S5: Gói Rẻ | T5: Gói Cơ bản | U5: Gói Nâng cao | V5: Gói Cao cấp
A6: 1.1 | B6: 1. Khởi động & phân tích | C6: Họp khởi động, chốt mục tiêu và phạm vi | D6: Biên bản phạm vi, danh sách chức năng theo mức ưu tiên | E6: PM/BA | F6: 0.5 | G6: =INDEX('Thông số'!$B$6:$B$10,MATCH(E6,'Thông số'!$A$6:$A$10,0))*'Thông số'!$B$26 -> 1050000 | H6: =F6*G6 -> 525000 | I6: 1 | J6: 1 | K6: 1 | L6: 1 | M6: 1 | N6: 1 | O6: 1 | P6: =F6*O6 -> 0.5 | Q6: =H6*O6 -> 525000 | R6: =IF(SUM(I6:N6)=0,"Tùy chọn","Trong gói") -> Trong gói | S6: 1 | T6: 1 | U6: 1 | V6: 1
A7: 1.2 | B7: 1. Khởi động & phân tích | C7: Phân tích nghiệp vụ và đặc tả chức năng | D7: Tài liệu đặc tả: user story, luồng nghiệp vụ | E7: PM/BA | F7: 3 | G7: =INDEX('Thông số'!$B$6:$B$10,MATCH(E7,'Thông số'!$A$6:$A$10,0))*'Thông số'!$B$26 -> 1050000 | H7: =F7*G7 -> 3150000 | I7: 0 | J7: 0 | K7: 1 | L7: 1 | M7: 1 | N7: 1 | O7: 1 | P7: =F7*O7 -> 3 | Q7: =H7*O7 -> 3150000 | R7: =IF(SUM(I7:N7)=0,"Tùy chọn","Trong gói") -> Trong gói | S7: 0 | T7: 0 | U7: 1 | V7: 1
A8: 1.3 | B8: 1. Khởi động & phân tích | C8: Sitemap và cấu trúc nội dung | D8: Sơ đồ trang, danh sách nội dung khách cần chuẩn bị | E8: PM/BA | F8: 1 | G8: =INDEX('Thông số'!$B$6:$B$10,MATCH(E8,'Thông số'!$A$6:$A$10,0))*'Thông số'!$B$26 -> 1050000 | H8: =F8*G8 -> 1050000 | I8: 0 | J8: 1 | K8: 1 | L8: 0 | M8: 0 | N8: 0 | O8: 1 | P8: =F8*O8 -> 1 | Q8: =H8*O8 -> 1050000 | R8: =IF(SUM(I8:N8)=0,"Tùy chọn","Trong gói") -> Trong gói | S8: 0 | T8: 1 | U8: 1 | V8: 1
A9: 1.4 | B9: 1. Khởi động & phân tích | C9: Thiết kế kiến trúc và cơ sở dữ liệu | D9: Sơ đồ kiến trúc, ERD, lựa chọn công nghệ | E9: Senior Dev | F9: 3 | G9: =INDEX('Thông số'!$B$6:$B$10,MATCH(E9,'Thông số'!$A$6:$A$10,0))*'Thông số'!$B$26 -> 1400000 | H9: =F9*G9 -> 4200000 | I9: 0 | J9: 0 | K9: 1 | L9: 1 | M9: 1 | N9: 1 | O9: 1 | P9: =F9*O9 -> 3 | Q9: =H9*O9 -> 4200000 | R9: =IF(SUM(I9:N9)=0,"Tùy chọn","Trong gói") -> Trong gói | S9: 0 | T9: 0 | U9: 1 | V9: 1
A10: 1.5 | B10: 1. Khởi động & phân tích | C10: Kế hoạch dự án và lộ trình bàn giao | D10: Mốc thời gian, tiêu chí nghiệm thu | E10: PM/BA | F10: 0.5 | G10: =INDEX('Thông số'!$B$6:$B$10,MATCH(E10,'Thông số'!$A$6:$A$10,0))*'Thông số'!$B$26 -> 1050000 | H10: =F10*G10 -> 525000 | I10: 1 | J10: 1 | K10: 1 | L10: 1 | M10: 1 | N10: 1 | O10: 1 | P10: =F10*O10 -> 0.5 | Q10: =H10*O10 -> 525000 | R10: =IF(SUM(I10:N10)=0,"Tùy chọn","Trong gói") -> Trong gói | S10: 1 | T10: 1 | U10: 1 | V10: 1
A11: 2.1 | B11: 2. Thiết kế UI/UX | C11: Moodboard và bộ nhận diện giao diện | D11: Style guide: màu, font, component, design tokens | E11: UI/UX | F11: 1 | G11: =INDEX('Thông số'!$B$6:$B$10,MATCH(E11,'Thông số'!$A$6:$A$10,0))*'Thông số'!$B$26 -> 1050000 | H11: =F11*G11 -> 1050000 | I11: 1 | J11: 1 | K11: 1 | L11: 1 | M11: 1 | N11: 1 | O11: 1 | P11: =F11*O11 -> 1 | Q11: =H11*O11 -> 1050000 | R11: =IF(SUM(I11:N11)=0,"Tùy chọn","Trong gói") -> Trong gói | S11: 1 | T11: 1 | U11: 1 | V11: 1
A12: 2.2 | B12: 2. Thiết kế UI/UX | C12: Thiết kế landing page (desktop và mobile) | D12: File thiết kế landing page | E12: UI/UX | F12: 3 | G12: =INDEX('Thông số'!$B$6:$B$10,MATCH(E12,'Thông số'!$A$6:$A$10,0))*'Thông số'!$B$26 -> 1050000 | H12: =F12*G12 -> 3150000 | I12: 1 | J12: 0 | K12: 0 | L12: 0 | M12: 0 | N12: 0 | O12: 0 | P12: =F12*O12 -> 0 | Q12: =H12*O12 -> 0 | R12: =IF(SUM(I12:N12)=0,"Tùy chọn","Trong gói") -> Trong gói | S12: 1 | T12: 0 | U12: 0 | V12: 0
A13: 2.3 | B13: 2. Thiết kế UI/UX | C13: Thiết kế website nhiều trang (5 đến 8 trang mẫu) | D13: File thiết kế các trang chính | E13: UI/UX | F13: 6 | G13: =INDEX('Thông số'!$B$6:$B$10,MATCH(E13,'Thông số'!$A$6:$A$10,0))*'Thông số'!$B$26 -> 1050000 | H13: =F13*G13 -> 6300000 | I13: 0 | J13: 1 | K13: 1 | L13: 0 | M13: 0 | N13: 0 | O13: 1 | P13: =F13*O13 -> 6 | Q13: =H13*O13 -> 6300000 | R13: =IF(SUM(I13:N13)=0,"Tùy chọn","Trong gói") -> Trong gói | S13: 0 | T13: 1 | U13: 1 | V13: 1
A14: 2.4 | B14: 2. Thiết kế UI/UX | C14: Thiết kế giao diện quản trị | D14: Dashboard, danh sách, biểu mẫu, trạng thái rỗng | E14: UI/UX | F14: 6 | G14: =INDEX('Thông số'!$B$6:$B$10,MATCH(E14,'Thông số'!$A$6:$A$10,0))*'Thông số'!$B$26 -> 1050000 | H14: =F14*G14 -> 6300000 | I14: 0 | J14: 0 | K14: 1 | L14: 1 | M14: 1 | N14: 0 | O14: 1 | P14: =F14*O14 -> 6 | Q14: =H14*O14 -> 6300000 | R14: =IF(SUM(I14:N14)=0,"Tùy chọn","Trong gói") -> Trong gói | S14: 0 | T14: 0 | U14: 1 | V14: 1
A15: 2.5 | B15: 2. Thiết kế UI/UX | C15: Thiết kế giao diện mobile cho hệ thống | D15: Bản mobile của danh sách, biểu mẫu, điều hướng | E15: UI/UX | F15: 3 | G15: =INDEX('Thông số'!$B$6:$B$10,MATCH(E15,'Thông số'!$A$6:$A$10,0))*'Thông số'!$B$26 -> 1050000 | H15: =F15*G15 -> 3150000 | I15: 0 | J15: 0 | K15: 0 | L15: 1 | M15: 1 | N15: 0 | O15: 0 | P15: =F15*O15 -> 0 | Q15: =H15*O15 -> 0 | R15: =IF(SUM(I15:N15)=0,"Tùy chọn","Trong gói") -> Trong gói | S15: 0 | T15: 0 | U15: 0 | V15: 0
A16: 2.6 | B16: 2. Thiết kế UI/UX | C16: Thiết kế Zalo Mini App (ZaUI) | D16: Màn hình Mini App theo chuẩn thiết kế của Zalo | E16: UI/UX | F16: 4 | G16: =INDEX('Thông số'!$B$6:$B$10,MATCH(E16,'Thông số'!$A$6:$A$10,0))*'Thông số'!$B$26 -> 1050000 | H16: =F16*G16 -> 4200000 | I16: 0 | J16: 0 | K16: 0 | L16: 0 | M16: 0 | N16: 1 | O16: 0 | P16: =F16*O16 -> 0 | Q16: =H16*O16 -> 0 | R16: =IF(SUM(I16:N16)=0,"Tùy chọn","Trong gói") -> Trong gói | S16: 0 | T16: 0 | U16: 0 | V16: 0
A17: 2.7 | B17: 2. Thiết kế UI/UX | C17: Prototype và duyệt thiết kế | D17: Prototype bấm được, tối đa số vòng chỉnh sửa trong Thông số | E17: UI/UX | F17: 1 | G17: =INDEX('Thông số'!$B$6:$B$10,MATCH(E17,'Thông số'!$A$6:$A$10,0))*'Thông số'!$B$26 -> 1050000 | H17: =F17*G17 -> 1050000 | I17: 1 | J17: 1 | K17: 1 | L17: 1 | M17: 1 | N17: 1 | O17: 1 | P17: =F17*O17 -> 1 | Q17: =H17*O17 -> 1050000 | R17: =IF(SUM(I17:N17)=0,"Tùy chọn","Trong gói") -> Trong gói | S17: 1 | T17: 1 | U17: 1 | V17: 1
... A76: 12.4 | B76: 12. Đào tạo & bàn giao | C76: Bàn giao mã nguồn và tài khoản | D76: Mã nguồn, tài khoản quản trị, tài khoản hạ tầng | E76: Senior Dev | F76: 0.5 | G76: =INDEX('Thông số'!$B$6:$B$10,MATCH(E76,'Thông số'!$A$6:$A$10,0))*'Thông số'!$B$26 -> 1400000 | H76: =F76*G76 -> 700000 | I76: 1 | J76: 1 | K76: 1 | L76: 1 | M76: 1 | N76: 1 | O76: 1 | P76: =F76*O76 -> 0.5 | Q76: =H76*O76 -> 700000 | R76: =IF(SUM(I76:N76)=0,"Tùy chọn","Trong gói") -> Trong gói | S76: 1 | T76: 1 | U76: 1 | V76: 1
C77: Tổng theo từng gói / tổng đã chọn | D77: Thành tiền trước quản lý dự án, dự phòng, VAT | F77: =SUMPRODUCT(F6:F76,O6:O76) -> 80 | I77: =SUMPRODUCT(I6:I76,$H$6:$H$76) -> 23800000 | J77: =SUMPRODUCT(J6:J76,$H$6:$H$76) -> 35000000 | K77: =SUMPRODUCT(K6:K76,$H$6:$H$76) -> 102900000 | L77: =SUMPRODUCT(L6:L76,$H$6:$H$76) -> 126000000 | M77: =SUMPRODUCT(M6:M76,$H$6:$H$76) -> 143500000 | N77: =SUMPRODUCT(N6:N76,$H$6:$H$76) -> 90650000 | O77: =SUM(O6:O76) -> 32 | P77: =SUM(P6:P76) -> 80 | Q77: =SUM(Q6:Q76) -> 102900000 | S77: =SUMPRODUCT(S6:S76,$H$6:$H$76) -> 22400000 | T77: =SUMPRODUCT(T6:T76,$H$6:$H$76) -> 35000000 | U77: =SUMPRODUCT(U6:U76,$H$6:$H$76) -> 102900000 | V77: =SUMPRODUCT(V6:V76,$H$6:$H$76) -> 136500000

Sheet Gói cấp độ
A1: BẢNG BÁO GIÁ CHỨC NĂNG WEBSITE THEO CẤP ĐỘ
A2: Nguyễn Phan Minh Phú · Senior Software Engineer · npmphu97@gmail.com · 0379 774 886
A4: STT | B4: Tên chức năng | C4: Mã hạng mục 1 | D4: Mã hạng mục 2 | E4: Gói Rẻ | F4: Gói Cơ bản | G4: Gói Nâng cao | H4: Gói Cao cấp
B5: Giá gói (chưa VAT) | E5: ='Bảng giá đề xuất'!F6 -> 5000000 | F5: ='Bảng giá đề xuất'!F7 -> 12000000 | G5: ='Bảng giá đề xuất'!F8 -> 28000000 | H5: ='Bảng giá đề xuất'!F9 -> 45000000
B6: Phù hợp với | E6: Giới thiệu nhanh, chạy quảng cáo, thu thông tin khách | F6: Doanh nghiệp cần hiện diện chuyên nghiệp, ít đổi nội dung | G6: Doanh nghiệp tự cập nhật nội dung, làm SEO lâu dài | H6: Cần đa ngôn ngữ, thanh toán, tích hợp và chức năng riêng
A7: 1 | B7: Landing page một trang | C7: 3.1 | E7: =IF(SUMPRODUCT((('Hạng mục'!$A$6:$A$76=$C7)+('Hạng mục'!$A$6:$A$76=$D7))*'Hạng mục'!$S$6:$S$76)>0,"✔ Có",IF(SUMPRODUCT((('Hạng mục'!$A$6:$A$76=$C7)+('Hạng mục'!$A$6:$A$76=$D7))*'Hạng mục'!$S$6:$V$76)=0,"＋ Tùy chọn","✘ Không")) -> ✔ Có | F7: =IF(SUMPRODUCT((('Hạng mục'!$A$6:$A$76=$C7)+('Hạng mục'!$A$6:$A$76=$D7))*'Hạng mục'!$T$6:$T$76)>0,"✔ Có",IF(SUMPRODUCT((('Hạng mục'!$A$6:$A$76=$C7)+('Hạng mục'!$A$6:$A$76=$D7))*'Hạng mục'!$S$6:$V$76)=0,"＋ Tùy chọn","✘ Không")) -> ✘ Không | G7: =IF(SUMPRODUCT((('Hạng mục'!$A$6:$A$76=$C7)+('Hạng mục'!$A$6:$A$76=$D7))*'Hạng mục'!$U$6:$U$76)>0,"✔ Có",IF(SUMPRODUCT((('Hạng mục'!$A$6:$A$76=$C7)+('Hạng mục'!$A$6:$A$76=$D7))*'Hạng mục'!$S$6:$V$76)=0,"＋ Tùy chọn","✘ Không")) -> ✘ Không | H7: =IF(SUMPRODUCT((('Hạng mục'!$A$6:$A$76=$C7)+('Hạng mục'!$A$6:$A$76=$D7))*'Hạng mục'!$V$6:$V$76)>0,"✔ Có",IF(SUMPRODUCT((('Hạng mục'!$A$6:$A$76=$C7)+('Hạng mục'!$A$6:$A$76=$D7))*'Hạng mục'!$S$6:$V$76)=0,"＋ Tùy chọn","✘ Không")) -> ✘ Không
A8: 2 | B8: Website nhiều trang: giới thiệu, sản phẩm/dịch vụ, tin tức | C8: 3.2 | E8: =IF(SUMPRODUCT((('Hạng mục'!$A$6:$A$76=$C8)+('Hạng mục'!$A$6:$A$76=$D8))*'Hạng mục'!$S$6:$S$76)>0,"✔ Có",IF(SUMPRODUCT((('Hạng mục'!$A$6:$A$76=$C8)+('Hạng mục'!$A$6:$A$76=$D8))*'Hạng mục'!$S$6:$V$76)=0,"＋ Tùy chọn","✘ Không")) -> ✘ Không | F8: =IF(SUMPRODUCT((('Hạng mục'!$A$6:$A$76=$C8)+('Hạng mục'!$A$6:$A$76=$D8))*'Hạng mục'!$T$6:$T$76)>0,"✔ Có",IF(SUMPRODUCT((('Hạng mục'!$A$6:$A$76=$C8)+('Hạng mục'!$A$6:$A$76=$D8))*'Hạng mục'!$S$6:$V$76)=0,"＋ Tùy chọn","✘ Không")) -> ✔ Có | G8: =IF(SUMPRODUCT((('Hạng mục'!$A$6:$A$76=$C8)+('Hạng mục'!$A$6:$A$76=$D8))*'Hạng mục'!$U$6:$U$76)>0,"✔ Có",IF(SUMPRODUCT((('Hạng mục'!$A$6:$A$76=$C8)+('Hạng mục'!$A$6:$A$76=$D8))*'Hạng mục'!$S$6:$V$76)=0,"＋ Tùy chọn","✘ Không")) -> ✔ Có | H8: =IF(SUMPRODUCT((('Hạng mục'!$A$6:$A$76=$C8)+('Hạng mục'!$A$6:$A$76=$D8))*'Hạng mục'!$V$6:$V$76)>0,"✔ Có",IF(SUMPRODUCT((('Hạng mục'!$A$6:$A$76=$C8)+('Hạng mục'!$A$6:$A$76=$D8))*'Hạng mục'!$S$6:$V$76)=0,"＋ Tùy chọn","✘ Không")) -> ✔ Có
A9: 3 | B9: Thiết kế theo bộ nhận diện thương hiệu | C9: 2.1 | E9: =IF(SUMPRODUCT((('Hạng mục'!$A$6:$A$76=$C9)+('Hạng mục'!$A$6:$A$76=$D9))*'Hạng mục'!$S$6:$S$76)>0,"✔ Có",IF(SUMPRODUCT((('Hạng mục'!$A$6:$A$76=$C9)+('Hạng mục'!$A$6:$A$76=$D9))*'Hạng mục'!$S$6:$V$76)=0,"＋ Tùy chọn","✘ Không")) -> ✔ Có | F9: =IF(SUMPRODUCT((('Hạng mục'!$A$6:$A$76=$C9)+('Hạng mục'!$A$6:$A$76=$D9))*'Hạng mục'!$T$6:$T$76)>0,"✔ Có",IF(SUMPRODUCT((('Hạng mục'!$A$6:$A$76=$C9)+('Hạng mục'!$A$6:$A$76=$D9))*'Hạng mục'!$S$6:$V$76)=0,"＋ Tùy chọn","✘ Không")) -> ✔ Có | G9: =IF(SUMPRODUCT((('Hạng mục'!$A$6:$A$76=$C9)+('Hạng mục'!$A$6:$A$76=$D9))*'Hạng mục'!$U$6:$U$76)>0,"✔ Có",IF(SUMPRODUCT((('Hạng mục'!$A$6:$A$76=$C9)+('Hạng mục'!$A$6:$A$76=$D9))*'Hạng mục'!$S$6:$V$76)=0,"＋ Tùy chọn","✘ Không")) -> ✔ Có | H9: =IF(SUMPRODUCT((('Hạng mục'!$A$6:$A$76=$C9)+('Hạng mục'!$A$6:$A$76=$D9))*'Hạng mục'!$V$6:$V$76)>0,"✔ Có",IF(SUMPRODUCT((('Hạng mục'!$A$6:$A$76=$C9)+('Hạng mục'!$A$6:$A$76=$D9))*'Hạng mục'!$S$6:$V$76)=0,"＋ Tùy chọn","✘ Không")) -> ✔ Có
A10: 4 | B10: Hỗ trợ giao diện di động, phù hợp mọi thiết bị | C10: 3.1 | D10: 3.2 | E10: =IF(SUMPRODUCT((('Hạng mục'!$A$6:$A$76=$C10)+('Hạng mục'!$A$6:$A$76=$D10))*'Hạng mục'!$S$6:$S$76)>0,"✔ Có",IF(SUMPRODUCT((('Hạng mục'!$A$6:$A$76=$C10)+('Hạng mục'!$A$6:$A$76=$D10))*'Hạng mục'!$S$6:$V$76)=0,"＋ Tùy chọn","✘ Không")) -> ✔ Có | F10: =IF(SUMPRODUCT((('Hạng mục'!$A$6:$A$76=$C10)+('Hạng mục'!$A$6:$A$76=$D10))*'Hạng mục'!$T$6:$T$76)>0,"✔ Có",IF(SUMPRODUCT((('Hạng mục'!$A$6:$A$76=$C10)+('Hạng mục'!$A$6:$A$76=$D10))*'Hạng mục'!$S$6:$V$76)=0,"＋ Tùy chọn","✘ Không")) -> ✔ Có | G10: =IF(SUMPRODUCT((('Hạng mục'!$A$6:$A$76=$C10)+('Hạng mục'!$A$6:$A$76=$D10))*'Hạng mục'!$U$6:$U$76)>0,"✔ Có",IF(SUMPRODUCT((('Hạng mục'!$A$6:$A$76=$C10)+('Hạng mục'!$A$6:$A$76=$D10))*'Hạng mục'!$S$6:$V$76)=0,"＋ Tùy chọn","✘ Không")) -> ✔ Có | H10: =IF(SUMPRODUCT((('Hạng mục'!$A$6:$A$76=$C10)+('Hạng mục'!$A$6:$A$76=$D10))*'Hạng mục'!$V$6:$V$76)>0,"✔ Có",IF(SUMPRODUCT((('Hạng mục'!$A$6:$A$76=$C10)+('Hạng mục'!$A$6:$A$76=$D10))*'Hạng mục'!$S$6:$V$76)=0,"＋ Tùy chọn","✘ Không")) -> ✔ Có
A11: 5 | B11: Giới thiệu sản phẩm/dịch vụ theo từng chuyên mục | C11: 2.3 | E11: =IF(SUMPRODUCT((('Hạng mục'!$A$6:$A$76=$C11)+('Hạng mục'!$A$6:$A$76=$D11))*'Hạng mục'!$S$6:$S$76)>0,"✔ Có",IF(SUMPRODUCT((('Hạng mục'!$A$6:$A$76=$C11)+('Hạng mục'!$A$6:$A$76=$D11))*'Hạng mục'!$S$6:$V$76)=0,"＋ Tùy chọn","✘ Không")) -> ✘ Không | F11: =IF(SUMPRODUCT((('Hạng mục'!$A$6:$A$76=$C11)+('Hạng mục'!$A$6:$A$76=$D11))*'Hạng mục'!$T$6:$T$76)>0,"✔ Có",IF(SUMPRODUCT((('Hạng mục'!$A$6:$A$76=$C11)+('Hạng mục'!$A$6:$A$76=$D11))*'Hạng mục'!$S$6:$V$76)=0,"＋ Tùy chọn","✘ Không")) -> ✔ Có | G11: =IF(SUMPRODUCT((('Hạng mục'!$A$6:$A$76=$C11)+('Hạng mục'!$A$6:$A$76=$D11))*'Hạng mục'!$U$6:$U$76)>0,"✔ Có",IF(SUMPRODUCT((('Hạng mục'!$A$6:$A$76=$C11)+('Hạng mục'!$A$6:$A$76=$D11))*'Hạng mục'!$S$6:$V$76)=0,"＋ Tùy chọn","✘ Không")) -> ✔ Có | H11: =IF(SUMPRODUCT((('Hạng mục'!$A$6:$A$76=$C11)+('Hạng mục'!$A$6:$A$76=$D11))*'Hạng mục'!$V$6:$V$76)>0,"✔ Có",IF(SUMPRODUCT((('Hạng mục'!$A$6:$A$76=$C11)+('Hạng mục'!$A$6:$A$76=$D11))*'Hạng mục'!$S$6:$V$76)=0,"＋ Tùy chọn","✘ Không")) -> ✔ Có
A12: 6 | B12: Form liên hệ, thư liên hệ gửi về email | C12: 3.4 | E12: =IF(SUMPRODUCT((('Hạng mục'!$A$6:$A$76=$C12)+('Hạng mục'!$A$6:$A$76=$D12))*'Hạng mục'!$S$6:$S$76)>0,"✔ Có",IF(SUMPRODUCT((('Hạng mục'!$A$6:$A$76=$C12)+('Hạng mục'!$A$6:$A$76=$D12))*'Hạng mục'!$S$6:$V$76)=0,"＋ Tùy chọn","✘ Không")) -> ✔ Có | F12: =IF(SUMPRODUCT((('Hạng mục'!$A$6:$A$76=$C12)+('Hạng mục'!$A$6:$A$76=$D12))*'Hạng mục'!$T$6:$T$76)>0,"✔ Có",IF(SUMPRODUCT((('Hạng mục'!$A$6:$A$76=$C12)+('Hạng mục'!$A$6:$A$76=$D12))*'Hạng mục'!$S$6:$V$76)=0,"＋ Tùy chọn","✘ Không")) -> ✔ Có | G12: =IF(SUMPRODUCT((('Hạng mục'!$A$6:$A$76=$C12)+('Hạng mục'!$A$6:$A$76=$D12))*'Hạng mục'!$U$6:$U$76)>0,"✔ Có",IF(SUMPRODUCT((('Hạng mục'!$A$6:$A$76=$C12)+('Hạng mục'!$A$6:$A$76=$D12))*'Hạng mục'!$S$6:$V$76)=0,"＋ Tùy chọn","✘ Không")) -> ✔ Có | H12: =IF(SUMPRODUCT((('Hạng mục'!$A$6:$A$76=$C12)+('Hạng mục'!$A$6:$A$76=$D12))*'Hạng mục'!$V$6:$V$76)>0,"✔ Có",IF(SUMPRODUCT((('Hạng mục'!$A$6:$A$76=$C12)+('Hạng mục'!$A$6:$A$76=$D12))*'Hạng mục'!$S$6:$V$76)=0,"＋ Tùy chọn","✘ Không")) -> ✔ Có
A13: 7 | B13: Tối ưu tốc độ và SEO kỹ thuật | C13: 3.3 | E13: =IF(SUMPRODUCT((('Hạng mục'!$A$6:$A$76=$C13)+('Hạng mục'!$A$6:$A$76=$D13))*'Hạng mục'!$S$6:$S$76)>0,"✔ Có",IF(SUMPRODUCT((('Hạng mục'!$A$6:$A$76=$C13)+('Hạng mục'!$A$6:$A$76=$D13))*'Hạng mục'!$S$6:$V$76)=0,"＋ Tùy chọn","✘ Không")) -> ✔ Có | F13: =IF(SUMPRODUCT((('Hạng mục'!$A$6:$A$76=$C13)+('Hạng mục'!$A$6:$A$76=$D13))*'Hạng mục'!$T$6:$T$76)>0,"✔ Có",IF(SUMPRODUCT((('Hạng mục'!$A$6:$A$76=$C13)+('Hạng mục'!$A$6:$A$76=$D13))*'Hạng mục'!$S$6:$V$76)=0,"＋ Tùy chọn","✘ Không")) -> ✔ Có | G13: =IF(SUMPRODUCT((('Hạng mục'!$A$6:$A$76=$C13)+('Hạng mục'!$A$6:$A$76=$D13))*'Hạng mục'!$U$6:$U$76)>0,"✔ Có",IF(SUMPRODUCT((('Hạng mục'!$A$6:$A$76=$C13)+('Hạng mục'!$A$6:$A$76=$D13))*'Hạng mục'!$S$6:$V$76)=0,"＋ Tùy chọn","✘ Không")) -> ✔ Có | H13: =IF(SUMPRODUCT((('Hạng mục'!$A$6:$A$76=$C13)+('Hạng mục'!$A$6:$A$76=$D13))*'Hạng mục'!$V$6:$V$76)>0,"✔ Có",IF(SUMPRODUCT((('Hạng mục'!$A$6:$A$76=$C13)+('Hạng mục'!$A$6:$A$76=$D13))*'Hạng mục'!$S$6:$V$76)=0,"＋ Tùy chọn","✘ Không")) -> ✔ Có
A14: 8 | B14: Theo dõi truy cập (Google Analytics, Pixel) | C14: 9.2 | E14: =IF(SUMPRODUCT((('Hạng mục'!$A$6:$A$76=$C14)+('Hạng mục'!$A$6:$A$76=$D14))*'Hạng mục'!$S$6:$S$76)>0,"✔ Có",IF(SUMPRODUCT((('Hạng mục'!$A$6:$A$76=$C14)+('Hạng mục'!$A$6:$A$76=$D14))*'Hạng mục'!$S$6:$V$76)=0,"＋ Tùy chọn","✘ Không")) -> ✘ Không | F14: =IF(SUMPRODUCT((('Hạng mục'!$A$6:$A$76=$C14)+('Hạng mục'!$A$6:$A$76=$D14))*'Hạng mục'!$T$6:$T$76)>0,"✔ Có",IF(SUMPRODUCT((('Hạng mục'!$A$6:$A$76=$C14)+('Hạng mục'!$A$6:$A$76=$D14))*'Hạng mục'!$S$6:$V$76)=0,"＋ Tùy chọn","✘ Không")) -> ✔ Có | G14: =IF(SUMPRODUCT((('Hạng mục'!$A$6:$A$76=$C14)+('Hạng mục'!$A$6:$A$76=$D14))*'Hạng mục'!$U$6:$U$76)>0,"✔ Có",IF(SUMPRODUCT((('Hạng mục'!$A$6:$A$76=$C14)+('Hạng mục'!$A$6:$A$76=$D14))*'Hạng mục'!$S$6:$V$76)=0,"＋ Tùy chọn","✘ Không")) -> ✔ Có | H14: =IF(SUMPRODUCT((('Hạng mục'!$A$6:$A$76=$C14)+('Hạng mục'!$A$6:$A$76=$D14))*'Hạng mục'!$V$6:$V$76)>0,"✔ Có",IF(SUMPRODUCT((('Hạng mục'!$A$6:$A$76=$C14)+('Hạng mục'!$A$6:$A$76=$D14))*'Hạng mục'!$S$6:$V$76)=0,"＋ Tùy chọn","✘ Không")) -> ✔ Có
A15: 9 | B15: Tên miền riêng và chứng chỉ SSL (HTTPS) | C15: 11.1 | E15: =IF(SUMPRODUCT((('Hạng mục'!$A$6:$A$76=$C15)+('Hạng mục'!$A$6:$A$76=$D15))*'Hạng mục'!$S$6:$S$76)>0,"✔ Có",IF(SUMPRODUCT((('Hạng mục'!$A$6:$A$76=$C15)+('Hạng mục'!$A$6:$A$76=$D15))*'Hạng mục'!$S$6:$V$76)=0,"＋ Tùy chọn","✘ Không")) -> ✔ Có | F15: =IF(SUMPRODUCT((('Hạng mục'!$A$6:$A$76=$C15)+('Hạng mục'!$A$6:$A$76=$D15))*'Hạng mục'!$T$6:$T$76)>0,"✔ Có",IF(SUMPRODUCT((('Hạng mục'!$A$6:$A$76=$C15)+('Hạng mục'!$A$6:$A$76=$D15))*'Hạng mục'!$S$6:$V$76)=0,"＋ Tùy chọn","✘ Không")) -> ✔ Có | G15: =IF(SUMPRODUCT((('Hạng mục'!$A$6:$A$76=$C15)+('Hạng mục'!$A$6:$A$76=$D15))*'Hạng mục'!$U$6:$U$76)>0,"✔ Có",IF(SUMPRODUCT((('Hạng mục'!$A$6:$A$76=$C15)+('Hạng mục'!$A$6:$A$76=$D15))*'Hạng mục'!$S$6:$V$76)=0,"＋ Tùy chọn","✘ Không")) -> ✔ Có | H15: =IF(SUMPRODUCT((('Hạng mục'!$A$6:$A$76=$C15)+('Hạng mục'!$A$6:$A$76=$D15))*'Hạng mục'!$V$6:$V$76)>0,"✔ Có",IF(SUMPRODUCT((('Hạng mục'!$A$6:$A$76=$C15)+('Hạng mục'!$A$6:$A$76=$D15))*'Hạng mục'!$S$6:$V$76)=0,"＋ Tùy chọn","✘ Không")) -> ✔ Có
A16: 10 | B16: Tự cập nhật bài viết và trang (CMS) | C16: 5.1 | E16: =IF(SUMPRODUCT((('Hạng mục'!$A$6:$A$76=$C16)+('Hạng mục'!$A$6:$A$76=$D16))*'Hạng mục'!$S$6:$S$76)>0,"✔ Có",IF(SUMPRODUCT((('Hạng mục'!$A$6:$A$76=$C16)+('Hạng mục'!$A$6:$A$76=$D16))*'Hạng mục'!$S$6:$V$76)=0,"＋ Tùy chọn","✘ Không")) -> ✘ Không | F16: =IF(SUMPRODUCT((('Hạng mục'!$A$6:$A$76=$C16)+('Hạng mục'!$A$6:$A$76=$D16))*'Hạng mục'!$T$6:$T$76)>0,"✔ Có",IF(SUMPRODUCT((('Hạng mục'!$A$6:$A$76=$C16)+('Hạng mục'!$A$6:$A$76=$D16))*'Hạng mục'!$S$6:$V$76)=0,"＋ Tùy chọn","✘ Không")) -> ✘ Không | G16: =IF(SUMPRODUCT((('Hạng mục'!$A$6:$A$76=$C16)+('Hạng mục'!$A$6:$A$76=$D16))*'Hạng mục'!$U$6:$U$76)>0,"✔ Có",IF(SUMPRODUCT((('Hạng mục'!$A$6:$A$76=$C16)+('Hạng mục'!$A$6:$A$76=$D16))*'Hạng mục'!$S$6:$V$76)=0,"＋ Tùy chọn","✘ Không")) -> ✔ Có | H16: =IF(SUMPRODUCT((('Hạng mục'!$A$6:$A$76=$C16)+('Hạng mục'!$A$6:$A$76=$D16))*'Hạng mục'!$V$6:$V$76)>0,"✔ Có",IF(SUMPRODUCT((('Hạng mục'!$A$6:$A$76=$C16)+('Hạng mục'!$A$6:$A$76=$D16))*'Hạng mục'!$S$6:$V$76)=0,"＋ Tùy chọn","✘ Không")) -> ✔ Có
A17: 11 | B17: Thư viện ảnh, video, hoạt động của công ty | C17: 5.2 | E17: =IF(SUMPRODUCT((('Hạng mục'!$A$6:$A$76=$C17)+('Hạng mục'!$A$6:$A$76=$D17))*'Hạng mục'!$S$6:$S$76)>0,"✔ Có",IF(SUMPRODUCT((('Hạng mục'!$A$6:$A$76=$C17)+('Hạng mục'!$A$6:$A$76=$D17))*'Hạng mục'!$S$6:$V$76)=0,"＋ Tùy chọn","✘ Không")) -> ✘ Không | F17: =IF(SUMPRODUCT((('Hạng mục'!$A$6:$A$76=$C17)+('Hạng mục'!$A$6:$A$76=$D17))*'Hạng mục'!$T$6:$T$76)>0,"✔ Có",IF(SUMPRODUCT((('Hạng mục'!$A$6:$A$76=$C17)+('Hạng mục'!$A$6:$A$76=$D17))*'Hạng mục'!$S$6:$V$76)=0,"＋ Tùy chọn","✘ Không")) -> ✘ Không | G17: =IF(SUMPRODUCT((('Hạng mục'!$A$6:$A$76=$C17)+('Hạng mục'!$A$6:$A$76=$D17))*'Hạng mục'!$U$6:$U$76)>0,"✔ Có",IF(SUMPRODUCT((('Hạng mục'!$A$6:$A$76=$C17)+('Hạng mục'!$A$6:$A$76=$D17))*'Hạng mục'!$S$6:$V$76)=0,"＋ Tùy chọn","✘ Không")) -> ✔ Có | H17: =IF(SUMPRODUCT((('Hạng mục'!$A$6:$A$76=$C17)+('Hạng mục'!$A$6:$A$76=$D17))*'Hạng mục'!$V$6:$V$76)>0,"✔ Có",IF(SUMPRODUCT((('Hạng mục'!$A$6:$A$76=$C17)+('Hạng mục'!$A$6:$A$76=$D17))*'Hạng mục'!$S$6:$V$76)=0,"＋ Tùy chọn","✘ Không")) -> ✔ Có
A18: 12 | B18: Quản lý menu, banner, SEO từng trang | C18: 5.3 | E18: =IF(SUMPRODUCT((('Hạng mục'!$A$6:$A$76=$C18)+('Hạng mục'!$A$6:$A$76=$D18))*'Hạng mục'!$S$6:$S$76)>0,"✔ Có",IF(SUMPRODUCT((('Hạng mục'!$A$6:$A$76=$C18)+('Hạng mục'!$A$6:$A$76=$D18))*'Hạng mục'!$S$6:$V$76)=0,"＋ Tùy chọn","✘ Không")) -> ✘ Không | F18: =IF(SUMPRODUCT((('Hạng mục'!$A$6:$A$76=$C18)+('Hạng mục'!$A$6:$A$76=$D18))*'Hạng mục'!$T$6:$T$76)>0,"✔ Có",IF(SUMPRODUCT((('Hạng mục'!$A$6:$A$76=$C18)+('Hạng mục'!$A$6:$A$76=$D18))*'Hạng mục'!$S$6:$V$76)=0,"＋ Tùy chọn","✘ Không")) -> ✘ Không | G18: =IF(SUMPRODUCT((('Hạng mục'!$A$6:$A$76=$C18)+('Hạng mục'!$A$6:$A$76=$D18))*'Hạng mục'!$U$6:$U$76)>0,"✔ Có",IF(SUMPRODUCT((('Hạng mục'!$A$6:$A$76=$C18)+('Hạng mục'!$A$6:$A$76=$D18))*'Hạng mục'!$S$6:$V$76)=0,"＋ Tùy chọn","✘ Không")) -> ✔ Có | H18: =IF(SUMPRODUCT((('Hạng mục'!$A$6:$A$76=$C18)+('Hạng mục'!$A$6:$A$76=$D18))*'Hạng mục'!$V$6:$V$76)>0,"✔ Có",IF(SUMPRODUCT((('Hạng mục'!$A$6:$A$76=$C18)+('Hạng mục'!$A$6:$A$76=$D18))*'Hạng mục'!$S$6:$V$76)=0,"＋ Tùy chọn","✘ Không")) -> ✔ Có
A19: 13 | B19: Đăng bài theo lịch, khôi phục phiên bản cũ | C19: 5.4 | E19: =IF(SUMPRODUCT((('Hạng mục'!$A$6:$A$76=$C19)+('Hạng mục'!$A$6:$A$76=$D19))*'Hạng mục'!$S$6:$S$76)>0,"✔ Có",IF(SUMPRODUCT((('Hạng mục'!$A$6:$A$76=$C19)+('Hạng mục'!$A$6:$A$76=$D19))*'Hạng mục'!$S$6:$V$76)=0,"＋ Tùy chọn","✘ Không")) -> ✘ Không | F19: =IF(SUMPRODUCT((('Hạng mục'!$A$6:$A$76=$C19)+('Hạng mục'!$A$6:$A$76=$D19))*'Hạng mục'!$T$6:$T$76)>0,"✔ Có",IF(SUMPRODUCT((('Hạng mục'!$A$6:$A$76=$C19)+('Hạng mục'!$A$6:$A$76=$D19))*'Hạng mục'!$S$6:$V$76)=0,"＋ Tùy chọn","✘ Không")) -> ✘ Không | G19: =IF(SUMPRODUCT((('Hạng mục'!$A$6:$A$76=$C19)+('Hạng mục'!$A$6:$A$76=$D19))*'Hạng mục'!$U$6:$U$76)>0,"✔ Có",IF(SUMPRODUCT((('Hạng mục'!$A$6:$A$76=$C19)+('Hạng mục'!$A$6:$A$76=$D19))*'Hạng mục'!$S$6:$V$76)=0,"＋ Tùy chọn","✘ Không")) -> ✔ Có | H19: =IF(SUMPRODUCT((('Hạng mục'!$A$6:$A$76=$C19)+('Hạng mục'!$A$6:$A$76=$D19))*'Hạng mục'!$V$6:$V$76)>0,"✔ Có",IF(SUMPRODUCT((('Hạng mục'!$A$6:$A$76=$C19)+('Hạng mục'!$A$6:$A$76=$D19))*'Hạng mục'!$S$6:$V$76)=0,"＋ Tùy chọn","✘ Không")) -> ✔ Có
A20: 14 | B20: Trang quản trị, đăng nhập, phân quyền | C20: 4.2 | E20: =IF(SUMPRODUCT((('Hạng mục'!$A$6:$A$76=$C20)+('Hạng mục'!$A$6:$A$76=$D20))*'Hạng mục'!$S$6:$S$76)>0,"✔ Có",IF(SUMPRODUCT((('Hạng mục'!$A$6:$A$76=$C20)+('Hạng mục'!$A$6:$A$76=$D20))*'Hạng mục'!$S$6:$V$76)=0,"＋ Tùy chọn","✘ Không")) -> ✘ Không | F20: =IF(SUMPRODUCT((('Hạng mục'!$A$6:$A$76=$C20)+('Hạng mục'!$A$6:$A$76=$D20))*'Hạng mục'!$T$6:$T$76)>0,"✔ Có",IF(SUMPRODUCT((('Hạng mục'!$A$6:$A$76=$C20)+('Hạng mục'!$A$6:$A$76=$D20))*'Hạng mục'!$S$6:$V$76)=0,"＋ Tùy chọn","✘ Không")) -> ✘ Không | G20: =IF(SUMPRODUCT((('Hạng mục'!$A$6:$A$76=$C20)+('Hạng mục'!$A$6:$A$76=$D20))*'Hạng mục'!$U$6:$U$76)>0,"✔ Có",IF(SUMPRODUCT((('Hạng mục'!$A$6:$A$76=$C20)+('Hạng mục'!$A$6:$A$76=$D20))*'Hạng mục'!$S$6:$V$76)=0,"＋ Tùy chọn","✘ Không")) -> ✔ Có | H20: =IF(SUMPRODUCT((('Hạng mục'!$A$6:$A$76=$C20)+('Hạng mục'!$A$6:$A$76=$D20))*'Hạng mục'!$V$6:$V$76)>0,"✔ Có",IF(SUMPRODUCT((('Hạng mục'!$A$6:$A$76=$C20)+('Hạng mục'!$A$6:$A$76=$D20))*'Hạng mục'!$S$6:$V$76)=0,"＋ Tùy chọn","✘ Không")) -> ✔ Có
A21: 15 | B21: Email thông báo tự động (đơn hàng, liên hệ) | C21: 9.1 | E21: =IF(SUMPRODUCT((('Hạng mục'!$A$6:$A$76=$C21)+('Hạng mục'!$A$6:$A$76=$D21))*'Hạng mục'!$S$6:$S$76)>0,"✔ Có",IF(SUMPRODUCT((('Hạng mục'!$A$6:$A$76=$C21)+('Hạng mục'!$A$6:$A$76=$D21))*'Hạng mục'!$S$6:$V$76)=0,"＋ Tùy chọn","✘ Không")) -> ✘ Không | F21: =IF(SUMPRODUCT((('Hạng mục'!$A$6:$A$76=$C21)+('Hạng mục'!$A$6:$A$76=$D21))*'Hạng mục'!$T$6:$T$76)>0,"✔ Có",IF(SUMPRODUCT((('Hạng mục'!$A$6:$A$76=$C21)+('Hạng mục'!$A$6:$A$76=$D21))*'Hạng mục'!$S$6:$V$76)=0,"＋ Tùy chọn","✘ Không")) -> ✘ Không | G21: =IF(SUMPRODUCT((('Hạng mục'!$A$6:$A$76=$C21)+('Hạng mục'!$A$6:$A$76=$D21))*'Hạng mục'!$U$6:$U$76)>0,"✔ Có",IF(SUMPRODUCT((('Hạng mục'!$A$6:$A$76=$C21)+('Hạng mục'!$A$6:$A$76=$D21))*'Hạng mục'!$S$6:$V$76)=0,"＋ Tùy chọn","✘ Không")) -> ✘ Không | H21: =IF(SUMPRODUCT((('Hạng mục'!$A$6:$A$76=$C21)+('Hạng mục'!$A$6:$A$76=$D21))*'Hạng mục'!$V$6:$V$76)>0,"✔ Có",IF(SUMPRODUCT((('Hạng mục'!$A$6:$A$76=$C21)+('Hạng mục'!$A$6:$A$76=$D21))*'Hạng mục'!$S$6:$V$76)=0,"＋ Tùy chọn","✘ Không")) -> ✔ Có
A22: 16 | B22: Hỗ trợ đa ngôn ngữ (Việt/Anh) | C22: 3.8 | E22: =IF(SUMPRODUCT((('Hạng mục'!$A$6:$A$76=$C22)+('Hạng mục'!$A$6:$A$76=$D22))*'Hạng mục'!$S$6:$S$76)>0,"✔ Có",IF(SUMPRODUCT((('Hạng mục'!$A$6:$A$76=$C22)+('Hạng mục'!$A$6:$A$76=$D22))*'Hạng mục'!$S$6:$V$76)=0,"＋ Tùy chọn","✘ Không")) -> ✘ Không | F22: =IF(SUMPRODUCT((('Hạng mục'!$A$6:$A$76=$C22)+('Hạng mục'!$A$6:$A$76=$D22))*'Hạng mục'!$T$6:$T$76)>0,"✔ Có",IF(SUMPRODUCT((('Hạng mục'!$A$6:$A$76=$C22)+('Hạng mục'!$A$6:$A$76=$D22))*'Hạng mục'!$S$6:$V$76)=0,"＋ Tùy chọn","✘ Không")) -> ✘ Không | G22: =IF(SUMPRODUCT((('Hạng mục'!$A$6:$A$76=$C22)+('Hạng mục'!$A$6:$A$76=$D22))*'Hạng mục'!$U$6:$U$76)>0,"✔ Có",IF(SUMPRODUCT((('Hạng mục'!$A$6:$A$76=$C22)+('Hạng mục'!$A$6:$A$76=$D22))*'Hạng mục'!$S$6:$V$76)=0,"＋ Tùy chọn","✘ Không")) -> ✘ Không | H22: =IF(SUMPRODUCT((('Hạng mục'!$A$6:$A$76=$C22)+('Hạng mục'!$A$6:$A$76=$D22))*'Hạng mục'!$V$6:$V$76)>0,"✔ Có",IF(SUMPRODUCT((('Hạng mục'!$A$6:$A$76=$C22)+('Hạng mục'!$A$6:$A$76=$D22))*'Hạng mục'!$S$6:$V$76)=0,"＋ Tùy chọn","✘ Không")) -> ✔ Có
... A26: 20 | B26: Giám sát, cảnh báo và sao lưu tự động | C26: 11.5 | E26: =IF(SUMPRODUCT((('Hạng mục'!$A$6:$A$76=$C26)+('Hạng mục'!$A$6:$A$76=$D26))*'Hạng mục'!$S$6:$S$76)>0,"✔ Có",IF(SUMPRODUCT((('Hạng mục'!$A$6:$A$76=$C26)+('Hạng mục'!$A$6:$A$76=$D26))*'Hạng mục'!$S$6:$V$76)=0,"＋ Tùy chọn","✘ Không")) -> ✘ Không | F26: =IF(SUMPRODUCT((('Hạng mục'!$A$6:$A$76=$C26)+('Hạng mục'!$A$6:$A$76=$D26))*'Hạng mục'!$T$6:$T$76)>0,"✔ Có",IF(SUMPRODUCT((('Hạng mục'!$A$6:$A$76=$C26)+('Hạng mục'!$A$6:$A$76=$D26))*'Hạng mục'!$S$6:$V$76)=0,"＋ Tùy chọn","✘ Không")) -> ✘ Không | G26: =IF(SUMPRODUCT((('Hạng mục'!$A$6:$A$76=$C26)+('Hạng mục'!$A$6:$A$76=$D26))*'Hạng mục'!$U$6:$U$76)>0,"✔ Có",IF(SUMPRODUCT((('Hạng mục'!$A$6:$A$76=$C26)+('Hạng mục'!$A$6:$A$76=$D26))*'Hạng mục'!$S$6:$V$76)=0,"＋ Tùy chọn","✘ Không")) -> ✔ Có | H26: =IF(SUMPRODUCT((('Hạng mục'!$A$6:$A$76=$C26)+('Hạng mục'!$A$6:$A$76=$D26))*'Hạng mục'!$V$6:$V$76)>0,"✔ Có",IF(SUMPRODUCT((('Hạng mục'!$A$6:$A$76=$C26)+('Hạng mục'!$A$6:$A$76=$D26))*'Hạng mục'!$S$6:$V$76)=0,"＋ Tùy chọn","✘ Không")) -> ✔ Có
A27: 21 | B27: Tài liệu hướng dẫn và đào tạo sử dụng | C27: 12.1 | D27: 12.3 | E27: =IF(SUMPRODUCT((('Hạng mục'!$A$6:$A$76=$C27)+('Hạng mục'!$A$6:$A$76=$D27))*'Hạng mục'!$S$6:$S$76)>0,"✔ Có",IF(SUMPRODUCT((('Hạng mục'!$A$6:$A$76=$C27)+('Hạng mục'!$A$6:$A$76=$D27))*'Hạng mục'!$S$6:$V$76)=0,"＋ Tùy chọn","✘ Không")) -> ✔ Có | F27: =IF(SUMPRODUCT((('Hạng mục'!$A$6:$A$76=$C27)+('Hạng mục'!$A$6:$A$76=$D27))*'Hạng mục'!$T$6:$T$76)>0,"✔ Có",IF(SUMPRODUCT((('Hạng mục'!$A$6:$A$76=$C27)+('Hạng mục'!$A$6:$A$76=$D27))*'Hạng mục'!$S$6:$V$76)=0,"＋ Tùy chọn","✘ Không")) -> ✔ Có | G27: =IF(SUMPRODUCT((('Hạng mục'!$A$6:$A$76=$C27)+('Hạng mục'!$A$6:$A$76=$D27))*'Hạng mục'!$U$6:$U$76)>0,"✔ Có",IF(SUMPRODUCT((('Hạng mục'!$A$6:$A$76=$C27)+('Hạng mục'!$A$6:$A$76=$D27))*'Hạng mục'!$S$6:$V$76)=0,"＋ Tùy chọn","✘ Không")) -> ✔ Có | H27: =IF(SUMPRODUCT((('Hạng mục'!$A$6:$A$76=$C27)+('Hạng mục'!$A$6:$A$76=$D27))*'Hạng mục'!$V$6:$V$76)>0,"✔ Có",IF(SUMPRODUCT((('Hạng mục'!$A$6:$A$76=$C27)+('Hạng mục'!$A$6:$A$76=$D27))*'Hạng mục'!$S$6:$V$76)=0,"＋ Tùy chọn","✘ Không")) -> ✔ Có
A28: 22 | B28: Chức năng theo yêu cầu riêng (khối lượng thỏa thuận) | C28: 9.7 | E28: =IF(SUMPRODUCT((('Hạng mục'!$A$6:$A$76=$C28)+('Hạng mục'!$A$6:$A$76=$D28))*'Hạng mục'!$S$6:$S$76)>0,"✔ Có",IF(SUMPRODUCT((('Hạng mục'!$A$6:$A$76=$C28)+('Hạng mục'!$A$6:$A$76=$D28))*'Hạng mục'!$S$6:$V$76)=0,"＋ Tùy chọn","✘ Không")) -> ✘ Không | F28: =IF(SUMPRODUCT((('Hạng mục'!$A$6:$A$76=$C28)+('Hạng mục'!$A$6:$A$76=$D28))*'Hạng mục'!$T$6:$T$76)>0,"✔ Có",IF(SUMPRODUCT((('Hạng mục'!$A$6:$A$76=$C28)+('Hạng mục'!$A$6:$A$76=$D28))*'Hạng mục'!$S$6:$V$76)=0,"＋ Tùy chọn","✘ Không")) -> ✘ Không | G28: =IF(SUMPRODUCT((('Hạng mục'!$A$6:$A$76=$C28)+('Hạng mục'!$A$6:$A$76=$D28))*'Hạng mục'!$U$6:$U$76)>0,"✔ Có",IF(SUMPRODUCT((('Hạng mục'!$A$6:$A$76=$C28)+('Hạng mục'!$A$6:$A$76=$D28))*'Hạng mục'!$S$6:$V$76)=0,"＋ Tùy chọn","✘ Không")) -> ✘ Không | H28: =IF(SUMPRODUCT((('Hạng mục'!$A$6:$A$76=$C28)+('Hạng mục'!$A$6:$A$76=$D28))*'Hạng mục'!$V$6:$V$76)>0,"✔ Có",IF(SUMPRODUCT((('Hạng mục'!$A$6:$A$76=$C28)+('Hạng mục'!$A$6:$A$76=$D28))*'Hạng mục'!$S$6:$V$76)=0,"＋ Tùy chọn","✘ Không")) -> ✔ Có
B30: Giá và thời gian
B31: Giá đề xuất (chưa VAT) | E31: ='Bảng giá đề xuất'!F6 -> 5000000 | F31: ='Bảng giá đề xuất'!F7 -> 12000000 | G31: ='Bảng giá đề xuất'!F8 -> 28000000 | H31: ='Bảng giá đề xuất'!F9 -> 45000000
B32: VAT | E32: =E31*'Thông số'!$B$16 -> 500000 | F32: =F31*'Thông số'!$B$16 -> 1200000 | G32: =G31*'Thông số'!$B$16 -> 2800000 | H32: =H31*'Thông số'!$B$16 -> 4500000
B33: TỔNG CỘNG (đã gồm VAT) | E33: =E31+E32 -> 5500000 | F33: =F31+F32 -> 13200000 | G33: =G31+G32 -> 30800000 | H33: =H31+H32 -> 49500000
B34: Số người tham gia | E34: 1 | F34: 1 | G34: 2 | H34: 3
B35: Thời gian dự kiến (tuần) | E35: =ROUNDUP('Bảng giá đề xuất'!H6*(1+'Thông số'!$B$14)/(E34*'Thông số'!$B$17*'Thông số'!$B$18),0) -> 1 | F35: =ROUNDUP('Bảng giá đề xuất'!H7*(1+'Thông số'!$B$14)/(F34*'Thông số'!$B$17*'Thông số'!$B$18),0) -> 2 | G35: =ROUNDUP('Bảng giá đề xuất'!H8*(1+'Thông số'!$B$14)/(G34*'Thông số'!$B$17*'Thông số'!$B$18),0) -> 2 | H35: =ROUNDUP('Bảng giá đề xuất'!H9*(1+'Thông số'!$B$14)/(H34*'Thông số'!$B$17*'Thông số'!$B$18),0) -> 3
B36: Gói vận hành hàng tháng | E36: Cơ bản | F36: Cơ bản | G36: Tiêu chuẩn | H36: Tiêu chuẩn
B37: Phí hàng tháng sau go-live (VND) | E37: =INDEX('Vận hành'!$I$24:$K$24,MATCH(E36,'Vận hành'!$I$5:$K$5,0)) -> 538333.33 | F37: =INDEX('Vận hành'!$I$24:$K$24,MATCH(F36,'Vận hành'!$I$5:$K$5,0)) -> 538333.33 | G37: =INDEX('Vận hành'!$I$24:$K$24,MATCH(G36,'Vận hành'!$I$5:$K$5,0)) -> 2653333.3 | H37: =INDEX('Vận hành'!$I$24:$K$24,MATCH(H36,'Vận hành'!$I$5:$K$5,0)) -> 2653333.3
A39: ✔ Có: đã gồm trong gói. ✘ Không: không gồm. ＋ Tùy chọn: không gồm trong cấp độ nào, báo giá thêm. Gói Cao cấp gồm khối lượng dành cho chức năng theo yêu cầu (mã 9.7), nếu vượt thì tính thêm theo đơn giá ngày công. Nâng cấp lên gói cao hơn chỉ trả phần chênh lệch.

Sheet So sánh gói
A1: BẢNG SO SÁNH CHỨC NĂNG THEO GÓI
A2: Nguyễn Phan Minh Phú · Senior Software Engineer · npmphu97@gmail.com · 0379 774 886
A4: STT | B4: Tên chức năng | C4: Mã hạng mục 1 | D4: Mã hạng mục 2 | E4: Landing page | F4: Website giới thiệu | G4: Website + CMS | H4: CRM | I4: Hệ thống quản lý | J4: Zalo Mini App
B5: Giá đề xuất (chưa VAT) | E5: ='Tổng hợp gói'!B32 -> 5000000 | F5: ='Tổng hợp gói'!C32 -> 12000000 | G5: ='Tổng hợp gói'!D32 -> 28000000 | H5: ='Tổng hợp gói'!E32 -> 85000000 | I5: ='Tổng hợp gói'!F32 -> 160000000 | J5: ='Tổng hợp gói'!G32 -> 30000000
B6: Phí hàng tháng sau go-live (gói đề xuất) | E6: ='Tổng hợp gói'!B31 -> 538333.33 | F6: ='Tổng hợp gói'!C31 -> 538333.33 | G6: ='Tổng hợp gói'!D31 -> 2653333.3 | H6: ='Tổng hợp gói'!E31 -> 2653333.3 | I6: ='Tổng hợp gói'!F31 -> 2653333.3 | J6: ='Tổng hợp gói'!G31 -> 538333.33
A7: 1 | B7: Landing page một trang, hiển thị tốt trên điện thoại | C7: 3.1 | E7: =IF(SUMPRODUCT((('Hạng mục'!$A$6:$A$76=$C7)+('Hạng mục'!$A$6:$A$76=$D7))*'Hạng mục'!$I$6:$I$76)>0,"✔ Có",IF(SUMPRODUCT((('Hạng mục'!$A$6:$A$76=$C7)+('Hạng mục'!$A$6:$A$76=$D7))*'Hạng mục'!$I$6:$N$76)=0,"＋ Tùy chọn","✘ Không")) -> ✔ Có | F7: =IF(SUMPRODUCT((('Hạng mục'!$A$6:$A$76=$C7)+('Hạng mục'!$A$6:$A$76=$D7))*'Hạng mục'!$J$6:$J$76)>0,"✔ Có",IF(SUMPRODUCT((('Hạng mục'!$A$6:$A$76=$C7)+('Hạng mục'!$A$6:$A$76=$D7))*'Hạng mục'!$I$6:$N$76)=0,"＋ Tùy chọn","✘ Không")) -> ✘ Không | G7: =IF(SUMPRODUCT((('Hạng mục'!$A$6:$A$76=$C7)+('Hạng mục'!$A$6:$A$76=$D7))*'Hạng mục'!$K$6:$K$76)>0,"✔ Có",IF(SUMPRODUCT((('Hạng mục'!$A$6:$A$76=$C7)+('Hạng mục'!$A$6:$A$76=$D7))*'Hạng mục'!$I$6:$N$76)=0,"＋ Tùy chọn","✘ Không")) -> ✘ Không | H7: =IF(SUMPRODUCT((('Hạng mục'!$A$6:$A$76=$C7)+('Hạng mục'!$A$6:$A$76=$D7))*'Hạng mục'!$L$6:$L$76)>0,"✔ Có",IF(SUMPRODUCT((('Hạng mục'!$A$6:$A$76=$C7)+('Hạng mục'!$A$6:$A$76=$D7))*'Hạng mục'!$I$6:$N$76)=0,"＋ Tùy chọn","✘ Không")) -> ✘ Không | I7: =IF(SUMPRODUCT((('Hạng mục'!$A$6:$A$76=$C7)+('Hạng mục'!$A$6:$A$76=$D7))*'Hạng mục'!$M$6:$M$76)>0,"✔ Có",IF(SUMPRODUCT((('Hạng mục'!$A$6:$A$76=$C7)+('Hạng mục'!$A$6:$A$76=$D7))*'Hạng mục'!$I$6:$N$76)=0,"＋ Tùy chọn","✘ Không")) -> ✘ Không | J7: =IF(SUMPRODUCT((('Hạng mục'!$A$6:$A$76=$C7)+('Hạng mục'!$A$6:$A$76=$D7))*'Hạng mục'!$N$6:$N$76)>0,"✔ Có",IF(SUMPRODUCT((('Hạng mục'!$A$6:$A$76=$C7)+('Hạng mục'!$A$6:$A$76=$D7))*'Hạng mục'!$I$6:$N$76)=0,"＋ Tùy chọn","✘ Không")) -> ✘ Không
A8: 2 | B8: Website nhiều trang: giới thiệu, sản phẩm/dịch vụ, tin tức | C8: 3.2 | E8: =IF(SUMPRODUCT((('Hạng mục'!$A$6:$A$76=$C8)+('Hạng mục'!$A$6:$A$76=$D8))*'Hạng mục'!$I$6:$I$76)>0,"✔ Có",IF(SUMPRODUCT((('Hạng mục'!$A$6:$A$76=$C8)+('Hạng mục'!$A$6:$A$76=$D8))*'Hạng mục'!$I$6:$N$76)=0,"＋ Tùy chọn","✘ Không")) -> ✘ Không | F8: =IF(SUMPRODUCT((('Hạng mục'!$A$6:$A$76=$C8)+('Hạng mục'!$A$6:$A$76=$D8))*'Hạng mục'!$J$6:$J$76)>0,"✔ Có",IF(SUMPRODUCT((('Hạng mục'!$A$6:$A$76=$C8)+('Hạng mục'!$A$6:$A$76=$D8))*'Hạng mục'!$I$6:$N$76)=0,"＋ Tùy chọn","✘ Không")) -> ✔ Có | G8: =IF(SUMPRODUCT((('Hạng mục'!$A$6:$A$76=$C8)+('Hạng mục'!$A$6:$A$76=$D8))*'Hạng mục'!$K$6:$K$76)>0,"✔ Có",IF(SUMPRODUCT((('Hạng mục'!$A$6:$A$76=$C8)+('Hạng mục'!$A$6:$A$76=$D8))*'Hạng mục'!$I$6:$N$76)=0,"＋ Tùy chọn","✘ Không")) -> ✔ Có | H8: =IF(SUMPRODUCT((('Hạng mục'!$A$6:$A$76=$C8)+('Hạng mục'!$A$6:$A$76=$D8))*'Hạng mục'!$L$6:$L$76)>0,"✔ Có",IF(SUMPRODUCT((('Hạng mục'!$A$6:$A$76=$C8)+('Hạng mục'!$A$6:$A$76=$D8))*'Hạng mục'!$I$6:$N$76)=0,"＋ Tùy chọn","✘ Không")) -> ✘ Không | I8: =IF(SUMPRODUCT((('Hạng mục'!$A$6:$A$76=$C8)+('Hạng mục'!$A$6:$A$76=$D8))*'Hạng mục'!$M$6:$M$76)>0,"✔ Có",IF(SUMPRODUCT((('Hạng mục'!$A$6:$A$76=$C8)+('Hạng mục'!$A$6:$A$76=$D8))*'Hạng mục'!$I$6:$N$76)=0,"＋ Tùy chọn","✘ Không")) -> ✘ Không | J8: =IF(SUMPRODUCT((('Hạng mục'!$A$6:$A$76=$C8)+('Hạng mục'!$A$6:$A$76=$D8))*'Hạng mục'!$N$6:$N$76)>0,"✔ Có",IF(SUMPRODUCT((('Hạng mục'!$A$6:$A$76=$C8)+('Hạng mục'!$A$6:$A$76=$D8))*'Hạng mục'!$I$6:$N$76)=0,"＋ Tùy chọn","✘ Không")) -> ✘ Không
A9: 3 | B9: Thiết kế theo bộ nhận diện thương hiệu | C9: 2.1 | E9: =IF(SUMPRODUCT((('Hạng mục'!$A$6:$A$76=$C9)+('Hạng mục'!$A$6:$A$76=$D9))*'Hạng mục'!$I$6:$I$76)>0,"✔ Có",IF(SUMPRODUCT((('Hạng mục'!$A$6:$A$76=$C9)+('Hạng mục'!$A$6:$A$76=$D9))*'Hạng mục'!$I$6:$N$76)=0,"＋ Tùy chọn","✘ Không")) -> ✔ Có | F9: =IF(SUMPRODUCT((('Hạng mục'!$A$6:$A$76=$C9)+('Hạng mục'!$A$6:$A$76=$D9))*'Hạng mục'!$J$6:$J$76)>0,"✔ Có",IF(SUMPRODUCT((('Hạng mục'!$A$6:$A$76=$C9)+('Hạng mục'!$A$6:$A$76=$D9))*'Hạng mục'!$I$6:$N$76)=0,"＋ Tùy chọn","✘ Không")) -> ✔ Có | G9: =IF(SUMPRODUCT((('Hạng mục'!$A$6:$A$76=$C9)+('Hạng mục'!$A$6:$A$76=$D9))*'Hạng mục'!$K$6:$K$76)>0,"✔ Có",IF(SUMPRODUCT((('Hạng mục'!$A$6:$A$76=$C9)+('Hạng mục'!$A$6:$A$76=$D9))*'Hạng mục'!$I$6:$N$76)=0,"＋ Tùy chọn","✘ Không")) -> ✔ Có | H9: =IF(SUMPRODUCT((('Hạng mục'!$A$6:$A$76=$C9)+('Hạng mục'!$A$6:$A$76=$D9))*'Hạng mục'!$L$6:$L$76)>0,"✔ Có",IF(SUMPRODUCT((('Hạng mục'!$A$6:$A$76=$C9)+('Hạng mục'!$A$6:$A$76=$D9))*'Hạng mục'!$I$6:$N$76)=0,"＋ Tùy chọn","✘ Không")) -> ✔ Có | I9: =IF(SUMPRODUCT((('Hạng mục'!$A$6:$A$76=$C9)+('Hạng mục'!$A$6:$A$76=$D9))*'Hạng mục'!$M$6:$M$76)>0,"✔ Có",IF(SUMPRODUCT((('Hạng mục'!$A$6:$A$76=$C9)+('Hạng mục'!$A$6:$A$76=$D9))*'Hạng mục'!$I$6:$N$76)=0,"＋ Tùy chọn","✘ Không")) -> ✔ Có | J9: =IF(SUMPRODUCT((('Hạng mục'!$A$6:$A$76=$C9)+('Hạng mục'!$A$6:$A$76=$D9))*'Hạng mục'!$N$6:$N$76)>0,"✔ Có",IF(SUMPRODUCT((('Hạng mục'!$A$6:$A$76=$C9)+('Hạng mục'!$A$6:$A$76=$D9))*'Hạng mục'!$I$6:$N$76)=0,"＋ Tùy chọn","✘ Không")) -> ✔ Có
A10: 4 | B10: Tối ưu tốc độ và SEO kỹ thuật | C10: 3.3 | E10: =IF(SUMPRODUCT((('Hạng mục'!$A$6:$A$76=$C10)+('Hạng mục'!$A$6:$A$76=$D10))*'Hạng mục'!$I$6:$I$76)>0,"✔ Có",IF(SUMPRODUCT((('Hạng mục'!$A$6:$A$76=$C10)+('Hạng mục'!$A$6:$A$76=$D10))*'Hạng mục'!$I$6:$N$76)=0,"＋ Tùy chọn","✘ Không")) -> ✔ Có | F10: =IF(SUMPRODUCT((('Hạng mục'!$A$6:$A$76=$C10)+('Hạng mục'!$A$6:$A$76=$D10))*'Hạng mục'!$J$6:$J$76)>0,"✔ Có",IF(SUMPRODUCT((('Hạng mục'!$A$6:$A$76=$C10)+('Hạng mục'!$A$6:$A$76=$D10))*'Hạng mục'!$I$6:$N$76)=0,"＋ Tùy chọn","✘ Không")) -> ✔ Có | G10: =IF(SUMPRODUCT((('Hạng mục'!$A$6:$A$76=$C10)+('Hạng mục'!$A$6:$A$76=$D10))*'Hạng mục'!$K$6:$K$76)>0,"✔ Có",IF(SUMPRODUCT((('Hạng mục'!$A$6:$A$76=$C10)+('Hạng mục'!$A$6:$A$76=$D10))*'Hạng mục'!$I$6:$N$76)=0,"＋ Tùy chọn","✘ Không")) -> ✔ Có | H10: =IF(SUMPRODUCT((('Hạng mục'!$A$6:$A$76=$C10)+('Hạng mục'!$A$6:$A$76=$D10))*'Hạng mục'!$L$6:$L$76)>0,"✔ Có",IF(SUMPRODUCT((('Hạng mục'!$A$6:$A$76=$C10)+('Hạng mục'!$A$6:$A$76=$D10))*'Hạng mục'!$I$6:$N$76)=0,"＋ Tùy chọn","✘ Không")) -> ✘ Không | I10: =IF(SUMPRODUCT((('Hạng mục'!$A$6:$A$76=$C10)+('Hạng mục'!$A$6:$A$76=$D10))*'Hạng mục'!$M$6:$M$76)>0,"✔ Có",IF(SUMPRODUCT((('Hạng mục'!$A$6:$A$76=$C10)+('Hạng mục'!$A$6:$A$76=$D10))*'Hạng mục'!$I$6:$N$76)=0,"＋ Tùy chọn","✘ Không")) -> ✘ Không | J10: =IF(SUMPRODUCT((('Hạng mục'!$A$6:$A$76=$C10)+('Hạng mục'!$A$6:$A$76=$D10))*'Hạng mục'!$N$6:$N$76)>0,"✔ Có",IF(SUMPRODUCT((('Hạng mục'!$A$6:$A$76=$C10)+('Hạng mục'!$A$6:$A$76=$D10))*'Hạng mục'!$I$6:$N$76)=0,"＋ Tùy chọn","✘ Không")) -> ✘ Không
A11: 5 | B11: Form liên hệ, thư gửi về email | C11: 3.4 | E11: =IF(SUMPRODUCT((('Hạng mục'!$A$6:$A$76=$C11)+('Hạng mục'!$A$6:$A$76=$D11))*'Hạng mục'!$I$6:$I$76)>0,"✔ Có",IF(SUMPRODUCT((('Hạng mục'!$A$6:$A$76=$C11)+('Hạng mục'!$A$6:$A$76=$D11))*'Hạng mục'!$I$6:$N$76)=0,"＋ Tùy chọn","✘ Không")) -> ✔ Có | F11: =IF(SUMPRODUCT((('Hạng mục'!$A$6:$A$76=$C11)+('Hạng mục'!$A$6:$A$76=$D11))*'Hạng mục'!$J$6:$J$76)>0,"✔ Có",IF(SUMPRODUCT((('Hạng mục'!$A$6:$A$76=$C11)+('Hạng mục'!$A$6:$A$76=$D11))*'Hạng mục'!$I$6:$N$76)=0,"＋ Tùy chọn","✘ Không")) -> ✔ Có | G11: =IF(SUMPRODUCT((('Hạng mục'!$A$6:$A$76=$C11)+('Hạng mục'!$A$6:$A$76=$D11))*'Hạng mục'!$K$6:$K$76)>0,"✔ Có",IF(SUMPRODUCT((('Hạng mục'!$A$6:$A$76=$C11)+('Hạng mục'!$A$6:$A$76=$D11))*'Hạng mục'!$I$6:$N$76)=0,"＋ Tùy chọn","✘ Không")) -> ✔ Có | H11: =IF(SUMPRODUCT((('Hạng mục'!$A$6:$A$76=$C11)+('Hạng mục'!$A$6:$A$76=$D11))*'Hạng mục'!$L$6:$L$76)>0,"✔ Có",IF(SUMPRODUCT((('Hạng mục'!$A$6:$A$76=$C11)+('Hạng mục'!$A$6:$A$76=$D11))*'Hạng mục'!$I$6:$N$76)=0,"＋ Tùy chọn","✘ Không")) -> ✔ Có | I11: =IF(SUMPRODUCT((('Hạng mục'!$A$6:$A$76=$C11)+('Hạng mục'!$A$6:$A$76=$D11))*'Hạng mục'!$M$6:$M$76)>0,"✔ Có",IF(SUMPRODUCT((('Hạng mục'!$A$6:$A$76=$C11)+('Hạng mục'!$A$6:$A$76=$D11))*'Hạng mục'!$I$6:$N$76)=0,"＋ Tùy chọn","✘ Không")) -> ✘ Không | J11: =IF(SUMPRODUCT((('Hạng mục'!$A$6:$A$76=$C11)+('Hạng mục'!$A$6:$A$76=$D11))*'Hạng mục'!$N$6:$N$76)>0,"✔ Có",IF(SUMPRODUCT((('Hạng mục'!$A$6:$A$76=$C11)+('Hạng mục'!$A$6:$A$76=$D11))*'Hạng mục'!$I$6:$N$76)=0,"＋ Tùy chọn","✘ Không")) -> ✘ Không
A12: 6 | B12: Theo dõi truy cập (Analytics, Pixel) | C12: 9.2 | E12: =IF(SUMPRODUCT((('Hạng mục'!$A$6:$A$76=$C12)+('Hạng mục'!$A$6:$A$76=$D12))*'Hạng mục'!$I$6:$I$76)>0,"✔ Có",IF(SUMPRODUCT((('Hạng mục'!$A$6:$A$76=$C12)+('Hạng mục'!$A$6:$A$76=$D12))*'Hạng mục'!$I$6:$N$76)=0,"＋ Tùy chọn","✘ Không")) -> ✔ Có | F12: =IF(SUMPRODUCT((('Hạng mục'!$A$6:$A$76=$C12)+('Hạng mục'!$A$6:$A$76=$D12))*'Hạng mục'!$J$6:$J$76)>0,"✔ Có",IF(SUMPRODUCT((('Hạng mục'!$A$6:$A$76=$C12)+('Hạng mục'!$A$6:$A$76=$D12))*'Hạng mục'!$I$6:$N$76)=0,"＋ Tùy chọn","✘ Không")) -> ✔ Có | G12: =IF(SUMPRODUCT((('Hạng mục'!$A$6:$A$76=$C12)+('Hạng mục'!$A$6:$A$76=$D12))*'Hạng mục'!$K$6:$K$76)>0,"✔ Có",IF(SUMPRODUCT((('Hạng mục'!$A$6:$A$76=$C12)+('Hạng mục'!$A$6:$A$76=$D12))*'Hạng mục'!$I$6:$N$76)=0,"＋ Tùy chọn","✘ Không")) -> ✔ Có | H12: =IF(SUMPRODUCT((('Hạng mục'!$A$6:$A$76=$C12)+('Hạng mục'!$A$6:$A$76=$D12))*'Hạng mục'!$L$6:$L$76)>0,"✔ Có",IF(SUMPRODUCT((('Hạng mục'!$A$6:$A$76=$C12)+('Hạng mục'!$A$6:$A$76=$D12))*'Hạng mục'!$I$6:$N$76)=0,"＋ Tùy chọn","✘ Không")) -> ✘ Không | I12: =IF(SUMPRODUCT((('Hạng mục'!$A$6:$A$76=$C12)+('Hạng mục'!$A$6:$A$76=$D12))*'Hạng mục'!$M$6:$M$76)>0,"✔ Có",IF(SUMPRODUCT((('Hạng mục'!$A$6:$A$76=$C12)+('Hạng mục'!$A$6:$A$76=$D12))*'Hạng mục'!$I$6:$N$76)=0,"＋ Tùy chọn","✘ Không")) -> ✘ Không | J12: =IF(SUMPRODUCT((('Hạng mục'!$A$6:$A$76=$C12)+('Hạng mục'!$A$6:$A$76=$D12))*'Hạng mục'!$N$6:$N$76)>0,"✔ Có",IF(SUMPRODUCT((('Hạng mục'!$A$6:$A$76=$C12)+('Hạng mục'!$A$6:$A$76=$D12))*'Hạng mục'!$I$6:$N$76)=0,"＋ Tùy chọn","✘ Không")) -> ✘ Không
